Workbook

Sheet الاعدادات
A1: الصنف | B1: تصنيف الحركة
A2: اكسليرا 13/175/70 | B2: كاوتش | I2: مبيعات كاش
A3: اكسليرا 15/195/65 | B3: كاوتش | D3: مبيعات كاش | I3: مبيعات اجل
A4: NOZA ECO 15/185/65 كاوتش سومو اكينا صينى | B4: كاوتش | D4: مبيعات اجل | I4: مبيعات اجل
A5: فيتور خط ابيض 14/195 عريض | B5: كاوتش | D5: مصروفات | I5: مبيعات كاش
A6: 14/5/114 جنط سبور صينى تويوتا غاطس SLP LG20-VL | B6: كاوتش | D6: مشتريات | I6: مبيعات كاش
A7: 14/5/114 جنط سبور صينى تويوتا غاطس | B7: كاوتش | I7: مبيعات كاش
A8: فيتور خط ابيض 14/195 كنزة | B8: كاوتش | I8: مبيعات كاش
A9: طقم جانط 5 خرم ملاكى 15 | B9: كاوتش | I9: مبيعات كاش
A10: فيتور خط ابيض 13/185/60 GALAXY F1 | B10: كاوتش | I10: مبيعات كاش
A11: فيتور 14/195 عريض | B11: كاوتش | I11: مبيعات كاش
A12: فيتور 14/195 كنزة | B12: كاوتش | I12: مبيعات كاش
A13: طقم جانط 14 BLP LG20-VL | B13: كاوتش | I13: مبيعات كاش
A14: كاوتش توكتوك | B14: كاوتش | I14: مبيعات كاش
A15: 14/5/144 BM-657-VL جنط سبور صينى غاطس | B15: كاوتش | I15: مبيعات كاش
A16: R14(5X114) BM/657 14/5/144 BM-657-VL جنط سبور صينى تويوتا غاطس | B16: كاوتش | I16: مبيعات كاش
A17: NOZA ECO 14/185/65 كاوتش سومو اكينا صينى | B17: كاوتش | I17: مبيعات كاش
A18: بلف كتينة | B18: قطع غيار | I18: مبيعات كاش
... A143: بطارية كلورايد 70 فيلدا | B143: بطارية | I143: مبيعات كاش
I144: مبيعات كاش
I145: مبيعات كاش
I146: مبيعات كاش
I147: مبيعات كاش
I148: مبيعات كاش
I149: مبيعات كاش
I150: مبيعات كاش
I151: مبيعات كاش
I152: مبيعات كاش
I153: مبيعات كاش
I154: مبيعات كاش
I155: مبيعات كاش
... I428: مصروفات

Sheet لوحة التحكم

Sheet دفتر اليومية
K3: =SUBTOTAL(9,K6:K1048576) -> 560605 | L3: =SUBTOTAL(9,L6:L1048576) -> 370955 | M3: =SUBTOTAL(9,M6:M1048576) -> 189650
B5: التاريخ | C5: الشهر | D5: الصنف | E5: نوع الحركة | F5: تصنيف الحركة | G5: رقم الفاتورة | H5: اسم العميل / المورد | I5: الكمية | J5: سعر الوحدة | K5: الاجمالي | L5: المسدد / المحصل | M5: المتبقى | T5: نوع الحركة | U5: تصنيف الحركة | AC5: الشهر
B6: 45834 | C6: =MONTH(B6) -> 6 | D6: اكسليرا 13/175/70 | E6: مبيعات كاش | F6: كاوتش | H6: Client 21 | I6: 1 | J6: 1750 | K6: =I6*J6 -> 1750 | L6: =K6 -> 1750 | M6: =K6-L6 -> 0 | Z6: 1 | AA6: Jan | AC6: =IFERROR(INDEX(AA:AA,MATCH(C6,Z:Z,0)),"") -> Jun
B7: 45830 | C7: =MONTH(B7) -> 6 | D7: فيتور 14/195 عريض | E7: مبيعات اجل | F7: كاوتش | H7: Client 19 | I7: 2 | J7: 4875 | K7: =I7*J7 -> 9750 | M7: =K7-L7 -> 9750 | Z7: 2 | AA7: Feb | AC7: =IFERROR(INDEX(AA:AA,MATCH(C7,Z:Z,0)),"") -> Jun
B8: 45830 | C8: =MONTH(B8) -> 6 | D8: فيتور 14/195 عريض | E8: مبيعات اجل | F8: كاوتش | H8: Client 15 | I8: 1 | J8: 5050 | K8: =I8*J8 -> 5050 | M8: =K8-L8 -> 5050 | Z8: 3 | AA8: Mar | AC8: =IFERROR(INDEX(AA:AA,MATCH(C8,Z:Z,0)),"") -> Jun
B9: 45840 | C9: =MONTH(B9) -> 7 | D9: بطارية كلورايد 70 معكوسة | E9: مبيعات كاش | F9: بطارية | H9: Client 16 | I9: 1 | J9: 1750 | K9: =I9*J9 -> 1750 | L9: =K9 -> 1750 | M9: =K9-L9 -> 0 | Z9: 4 | AA9: Apr | AC9: =IFERROR(INDEX(AA:AA,MATCH(C9,Z:Z,0)),"") -> Jul
B10: 45842 | C10: =MONTH(B10) -> 7 | D10: بلف كتينة | E10: مبيعات كاش | F10: قطع غيار | H10: Client 12 | I10: 5 | J10: 190 | K10: =I10*J10 -> 950 | L10: =K10 -> 950 | M10: =K10-L10 -> 0 | Z10: 5 | AA10: May | AC10: =IFERROR(INDEX(AA:AA,MATCH(C10,Z:Z,0)),"") -> Jul
B11: 45842 | C11: =MONTH(B11) -> 7 | D11: مروحة تويوتا عريضة | E11: مبيعات كاش | F11: قطع غيار | H11: Client 12 | I11: 5 | J11: 220 | K11: =I11*J11 -> 1100 | L11: =K11 -> 1100 | M11: =K11-L11 -> 0 | Z11: 6 | AA11: Jun | AC11: =IFERROR(INDEX(AA:AA,MATCH(C11,Z:Z,0)),"") -> Jul
B12: 45842 | C12: =MONTH(B12) -> 7 | D12: قميص رداتير | E12: مبيعات كاش | F12: قطع غيار | H12: Client 12 | I12: 5 | J12: 220 | K12: =I12*J12 -> 1100 | L12: =K12 -> 1100 | M12: =K12-L12 -> 0 | Z12: 7 | AA12: Jul | AC12: =IFERROR(INDEX(AA:AA,MATCH(C12,Z:Z,0)),"") -> Jul
B13: 45842 | C13: =MONTH(B13) -> 7 | D13: طقم جوان تويوتا | E13: مبيعات كاش | F13: قطع غيار | H13: Client 12 | I13: 1 | J13: 400 | K13: =I13*J13 -> 400 | L13: =K13 -> 400 | M13: =K13-L13 -> 0 | Z13: 8 | AA13: Aug | AC13: =IFERROR(INDEX(AA:AA,MATCH(C13,Z:Z,0)),"") -> Jul
B14: 45843 | C14: =MONTH(B14) -> 7 | D14: طقم تيل امامى | E14: مبيعات كاش | F14: قطع غيار | H14: Client 16 | I14: 1 | J14: 325 | K14: =I14*J14 -> 325 | L14: =K14 -> 325 | M14: =K14-L14 -> 0 | Z14: 9 | AA14: Sep | AC14: =IFERROR(INDEX(AA:AA,MATCH(C14,Z:Z,0)),"") -> Jul
B15: 45843 | C15: =MONTH(B15) -> 7 | D15: غطاء تنك | E15: مبيعات كاش | F15: قطع غيار | H15: Client 16 | I15: 1 | J15: 70 | K15: =I15*J15 -> 70 | L15: =K15 -> 70 | M15: =K15-L15 -> 0 | Z15: 10 | AA15: Oct | AC15: =IFERROR(INDEX(AA:AA,MATCH(C15,Z:Z,0)),"") -> Jul
B16: 45843 | C16: =MONTH(B16) -> 7 | D16: طقم تيل امامى | E16: مبيعات كاش | F16: قطع غيار | H16: Clinet 1 | I16: 1 | J16: 325 | K16: =I16*J16 -> 325 | L16: =K16 -> 325 | M16: =K16-L16 -> 0 | Z16: 11 | AA16: Nov | AC16: =IFERROR(INDEX(AA:AA,MATCH(C16,Z:Z,0)),"") -> Jul
B17: 45843 | C17: =MONTH(B17) -> 7 | D17: طقم بلية صره امامى + اويل سيل | E17: مبيعات كاش | F17: قطع غيار | H17: Clinet 1 | I17: 2 | J17: 175 | K17: =I17*J17 -> 350 | L17: =K17 -> 350 | M17: =K17-L17 -> 0 | Z17: 12 | AA17: Dec | AC17: =IFERROR(INDEX(AA:AA,MATCH(C17,Z:Z,0)),"") -> Jul
B18: 45843 | C18: =MONTH(B18) -> 7 | D18: طقم تيل امامى | E18: مبيعات كاش | F18: قطع غيار | H18: Client 16 | I18: 1 | J18: 325 | K18: =I18*J18 -> 325 | L18: =K18 -> 325 | M18: =K18-L18 -> 0 | AC18: =IFERROR(INDEX(AA:AA,MATCH(C18,Z:Z,0)),"") -> Jul
B19: 45843 | C19: =MONTH(B19) -> 7 | D19: طقم تيل امامى | E19: مبيعات كاش | F19: قطع غيار | H19: Client 12 | I19: 1 | J19: 325 | K19: =I19*J19 -> 325 | L19: =K19 -> 325 | M19: =K19-L19 -> 0 | AC19: =IFERROR(INDEX(AA:AA,MATCH(C19,Z:Z,0)),"") -> Jul
B20: 45843 | C20: =MONTH(B20) -> 7 | D20: طقم تيل امامى | E20: مبيعات كاش | F20: قطع غيار | H20: Clinet 1 | I20: 1 | J20: 325 | K20: =I20*J20 -> 325 | L20: =K20 -> 325 | M20: =K20-L20 -> 0 | AC20: =IFERROR(INDEX(AA:AA,MATCH(C20,Z:Z,0)),"") -> Jul
B21: 45843 | C21: =MONTH(B21) -> 7 | D21: طقم تيل امامى | E21: مبيعات كاش | F21: قطع غيار | H21: Client 15 | I21: 1 | J21: 325 | K21: =I21*J21 -> 325 | L21: =K21 -> 325 | M21: =K21-L21 -> 0 | AC21: =IFERROR(INDEX(AA:AA,MATCH(C21,Z:Z,0)),"") -> Jul
B22: 45843 | C22: =MONTH(B22) -> 7 | D22: تيل خلفى 902317 | E22: مبيعات كاش | F22: قطع غيار | H22: Client 15 | I22: 1 | J22: 920 | K22: =I22*J22 -> 920 | L22: =K22 -> 920 | M22: =K22-L22 -> 0 | AC22: =IFERROR(INDEX(AA:AA,MATCH(C22,Z:Z,0)),"") -> Jul
B23: 45843 | C23: =MONTH(B23) -> 7 | D23: بطارية نسر 70 | E23: مبيعات كاش | F23: بطارية | H23: Clinet 1 | I23: 1 | J23: 1350 | K23: =I23*J23 -> 1350 | L23: =K23 -> 1350 | M23: =K23-L23 -> 0 | AC23: =IFERROR(INDEX(AA:AA,MATCH(C23,Z:Z,0)),"") -> Jul
B24: 45843 | C24: =MONTH(B24) -> 7 | D24: شريحة اسبرتير | E24: مبيعات كاش | F24: قطع غيار | H24: Client 10 | I24: 1 | J24: 630 | K24: =I24*J24 -> 630 | L24: =K24 -> 630 | M24: =K24-L24 -> 0 | AC24: =IFERROR(INDEX(AA:AA,MATCH(C24,Z:Z,0)),"") -> Jul
B25: 45844 | C25: =MONTH(B25) -> 7 | D25: بطارية كلورايد 70 | E25: مبيعات كاش | F25: بطارية | H25: Clinet 2 | I25: 1 | J25: 1750 | K25: =I25*J25 -> 1750 | L25: =K25 -> 1750 | M25: =K25-L25 -> 0 | AC25: =IFERROR(INDEX(AA:AA,MATCH(C25,Z:Z,0)),"") -> Jul
B26: 45844 | C26: =MONTH(B26) -> 7 | D26: اكسليرا 13/175/70 | E26: مبيعات كاش | F26: كاوتش | H26: Client 16 | I26: 2 | J26: 1750 | K26: =I26*J26 -> 3500 | L26: =K26 -> 3500 | M26: =K26-L26 -> 0 | AC26: =IFERROR(INDEX(AA:AA,MATCH(C26,Z:Z,0)),"") -> Jul
B27: 45844 | C27: =MONTH(B27) -> 7 | D27: جوان وش سلندر | E27: مبيعات كاش | F27: قطع غيار | H27: Client 16 | I27: 1 | J27: 250 | K27: =I27*J27 -> 250 | L27: =K27 -> 250 | M27: =K27-L27 -> 0 | AC27: =IFERROR(INDEX(AA:AA,MATCH(C27,Z:Z,0)),"") -> Jul
B28: 45844 | C28: =MONTH(B28) -> 7 | D28: فلتر بنزين دايو /هيوندى | E28: مبيعات كاش | F28: قطع غيار | H28: Client 16 | I28: 1 | J28: 100 | K28: =I28*J28 -> 100 | L28: =K28 -> 100 | M28: =K28-L28 -> 0 | AC28: =IFERROR(INDEX(AA:AA,MATCH(C28,Z:Z,0)),"") -> Jul
B29: 45844 | C29: =MONTH(B29) -> 7 | D29: طقم تيل امامى | E29: مبيعات كاش | F29: قطع غيار | H29: Client 16 | I29: 1 | J29: 325 | K29: =I29*J29 -> 325 | L29: =K29 -> 325 | M29: =K29-L29 -> 0 | AC29: =IFERROR(INDEX(AA:AA,MATCH(C29,Z:Z,0)),"") -> Jul
... B335: 45869 | C335: =MONTH(B335) -> 7 | D335: باغة فانوس خلفى كريستال هاى اس شمال | E335: مبيعات كاش | F335: قطع غيار | H335: Client 16 | I335: 1 | J335: 100 | K335: =I335*J335 -> 100 | L335: =K335 -> 100 | M335: =K335-L335 -> 0 | AC335: =IFERROR(INDEX(AA:AA,MATCH(C335,Z:Z,0)),"") -> Jul
B336: 45843 | C336: =MONTH(B336) -> 7 | D336: بطارية 80 كلورايد | E336: مبيعات اجل | F336: بطارية | H336: Client 10 | I336: 1 | J336: 2850 | K336: =I336*J336 -> 2850 | M336: =K336-L336 -> 2850 | AC336: =IFERROR(INDEX(AA:AA,MATCH(C336,Z:Z,0)),"") -> Jul
B337: 45845 | C337: =MONTH(B337) -> 7 | D337: فيتور 14/195 كنزة | E337: مبيعات اجل | F337: كاوتش | H337: Client 20 | I337: 1 | J337: 3800 | K337: =I337*J337 -> 3800 | M337: =K337-L337 -> 3800 | AC337: =IFERROR(INDEX(AA:AA,MATCH(C337,Z:Z,0)),"") -> Jul
B338: 45847 | C338: =MONTH(B338) -> 7 | D338: فيتور 14/195 عريض | E338: مبيعات اجل | F338: كاوتش | H338: Client 20 | I338: 2 | J338: 4675 | K338: =I338*J338 -> 9350 | M338: =K338-L338 -> 9350 | AC338: =IFERROR(INDEX(AA:AA,MATCH(C338,Z:Z,0)),"") -> Jul
B339: 45848 | C339: =MONTH(B339) -> 7 | D339: فيتور 14/195 عريض | E339: مبيعات اجل | F339: كاوتش | H339: Client 10 | I339: 4 | J339: 4612.5 | K339: =I339*J339 -> 18450 | M339: =K339-L339 -> 18450 | AC339: =IFERROR(INDEX(AA:AA,MATCH(C339,Z:Z,0)),"") -> Jul
B340: 45848 | C340: =MONTH(B340) -> 7 | D340: طقم جانط 14 BLP LG20-VL | E340: مبيعات اجل | F340: كاوتش | H340: Client 19 | I340: 4 | J340: 4412.5 | K340: =I340*J340 -> 17650 | M340: =K340-L340 -> 17650 | AC340: =IFERROR(INDEX(AA:AA,MATCH(C340,Z:Z,0)),"") -> Jul
B341: 45850 | C341: =MONTH(B341) -> 7 | D341: فيتور 14/195 كنزة | E341: مبيعات اجل | F341: كاوتش | H341: Client 15 | I341: 4 | J341: 5000 | K341: =I341*J341 -> 20000 | M341: =K341-L341 -> 20000 | AC341: =IFERROR(INDEX(AA:AA,MATCH(C341,Z:Z,0)),"") -> Jul
B342: 45850 | C342: =MONTH(B342) -> 7 | D342: فيتور 14/195 عريض | E342: مبيعات اجل | F342: كاوتش | H342: Client 14 | I342: 1 | J342: 5150 | K342: =I342*J342 -> 5150 | M342: =K342-L342 -> 5150 | AC342: =IFERROR(INDEX(AA:AA,MATCH(C342,Z:Z,0)),"") -> Jul
B343: 45854 | C343: =MONTH(B343) -> 7 | D343: فيتور 14/195 كنزة | E343: مبيعات اجل | F343: كاوتش | H343: Client 17 | I343: 2 | J343: 4000 | K343: =I343*J343 -> 8000 | M343: =K343-L343 -> 8000 | AC343: =IFERROR(INDEX(AA:AA,MATCH(C343,Z:Z,0)),"") -> Jul
B344: 45854 | C344: =MONTH(B344) -> 7 | D344: فيتور 14/195 كنزة | E344: مبيعات اجل | F344: كاوتش | H344: Client 15 | I344: 2 | J344: 3975 | K344: =I344*J344 -> 7950 | M344: =K344-L344 -> 7950 | AC344: =IFERROR(INDEX(AA:AA,MATCH(C344,Z:Z,0)),"") -> Jul
B345: 45861 | C345: =MONTH(B345) -> 7 | D345: كاوتش توكتوك | E345: مبيعات اجل | F345: كاوتش | H345: Client 18 | I345: 2 | J345: 1250 | K345: =I345*J345 -> 2500 | M345: =K345-L345 -> 2500 | AC345: =IFERROR(INDEX(AA:AA,MATCH(C345,Z:Z,0)),"") -> Jul
B346: 45861 | C346: =MONTH(B346) -> 7 | D346: فيتور 14/195 عريض | E346: مبيعات اجل | F346: كاوتش | H346: Client 11 | I346: 2 | J346: 3975 | K346: =I346*J346 -> 7950 | M346: =K346-L346 -> 7950 | AC346: =IFERROR(INDEX(AA:AA,MATCH(C346,Z:Z,0)),"") -> Jul
B347: 45861 | C347: =MONTH(B347) -> 7 | D347: 14/5/144 BM-657-VL جنط سبور صينى غاطس | E347: مبيعات اجل | F347: كاوتش | H347: Client 19 | I347: 4 | J347: 4287.5 | K347: =I347*J347 -> 17150 | M347: =K347-L347 -> 17150 | AC347: =IFERROR(INDEX(AA:AA,MATCH(C347,Z:Z,0)),"") -> Jul
... B351: 45866 | C351: =MONTH(B351) -> 7 | D351: فيتور 14/195 عريض | E351: مبيعات اجل | F351: كاوتش | H351: Client 8 | I351: 2 | J351: 4775 | K351: =I351*J351 -> 9550 | M351: =K351-L351 -> 9550 | AC351: =IFERROR(INDEX(AA:AA,MATCH(C351,Z:Z,0)),"") -> Jul
...

Sheet رصيد العملاء
A2: نوع الحركة | B2: (Multiple Items)
A3: الشهر | B3: (All) | D3: =SUBTOTAL(9,D6:D1048576)/2 -> 188900
A5: العميل | B5: الاجمالي | C5: المسدد / المحصل | D5: المتبقى
A6: (blank) | B6: 1000 | D6: 1000
A7: Client 19 | B7: 44550 | D7: 44550
A8: Client 15 | B8: 66550 | D8: 66550
A9: Client 10 | B9: 24350 | D9: 24350
A10: Client 17 | B10: 8000 | D10: 8000
A11: Client 14 | B11: 7100 | D11: 7100
A12: Client 18 | B12: 6700 | D12: 6700
A13: Client 20 | B13: 13150 | D13: 13150
A14: Client 11 | B14: 7950 | D14: 7950
A15: Client 8 | B15: 9550 | D15: 9550
A16: الاجمالي | B16: 188900 | D16: 188900

Sheet Dashboard
C1: Dashboard
C3: إجمالى المبيعات | E3: إجمالي المشتريات | G3: إجمالى المصروفات | I3: إجمالى الربح | K3: إجمالى التحصيلات | M3: رصيد المخزن | O3: رصيد العملاء
C4: =SUMIFS('دفتر اليومية'!K:K,'دفتر اليومية'!E:E,"مبيعات كاش")+ SUMIFS('دفتر اليومية'!K:K,'دفتر اليومية'!E:E,"مبيعات آجل") -> 556855 | E4: =SUM(المشتريات!I:I) -> 2750 | G4: =SUMIFS('دفتر اليومية'!K:K,'دفتر اليومية'!E:E,"مصروفات") -> 1000 | I4: =C4-E4-G4 -> 553105 | K4: =SUM('دفتر اليومية'!L3) -> 370955 | M4: ='حركة المخزن'!L5 -> 110375 | O4: =SUM('⁠حسابات عملاء'!B2:B1169) -> 187900
A35: الشهر | B35: المبيعات | C35: المصروفات | D35: تكلفة البضاعة المباعة | E35: الربح
A36: Jan | B36: =SUMIFS('دفتر اليومية'!K:K,'دفتر اليومية'!AC:AC,A36,'دفتر اليومية'!E:E,"مبيعات كاش") +SUMIFS('دفتر اليومية'!K:K,'دفتر اليومية'!AC:AC,A36,'دفتر اليومية'!E:E,"مبيعات اجل") -> 0 | C36: =SUMIFS('دفتر اليومية'!K:K, 'دفتر اليومية'!E:E, "مصروفات", 'دفتر اليومية'!AC:AC, Dashboard!A36) -> 0 | D36: =SUMIFS('دفتر اليومية'!K:K, 'دفتر اليومية'!E:E, "مشتريات", 'دفتر اليومية'!AC:AC, Dashboard!A36) -> 0 | E36: =B36-C36-D36 -> 0
A37: Feb | B37: =SUMIFS('دفتر اليومية'!K:K,'دفتر اليومية'!AC:AC,A37,'دفتر اليومية'!E:E,"مبيعات كاش") +SUMIFS('دفتر اليومية'!K:K,'دفتر اليومية'!AC:AC,A37,'دفتر اليومية'!E:E,"مبيعات اجل") -> 0 | C37: =SUMIFS('دفتر اليومية'!K:K, 'دفتر اليومية'!E:E, "مصروفات", 'دفتر اليومية'!AC:AC, Dashboard!A37) -> 0 | D37: =SUMIFS('دفتر اليومية'!K:K, 'دفتر اليومية'!E:E, "مشتريات", 'دفتر اليومية'!AC:AC, Dashboard!A37) -> 0 | E37: =B37-C37-D37 -> 0
A38: Mar | B38: =SUMIFS('دفتر اليومية'!K:K,'دفتر اليومية'!AC:AC,A38,'دفتر اليومية'!E:E,"مبيعات كاش") +SUMIFS('دفتر اليومية'!K:K,'دفتر اليومية'!AC:AC,A38,'دفتر اليومية'!E:E,"مبيعات اجل") -> 0 | C38: =SUMIFS('دفتر اليومية'!K:K, 'دفتر اليومية'!E:E, "مصروفات", 'دفتر اليومية'!AC:AC, Dashboard!A38) -> 0 | D38: =SUMIFS('دفتر اليومية'!K:K, 'دفتر اليومية'!E:E, "مشتريات", 'دفتر اليومية'!AC:AC, Dashboard!A38) -> 0 | E38: =B38-C38-D38 -> 0
A39: Apr | B39: =SUMIFS('دفتر اليومية'!K:K,'دفتر اليومية'!AC:AC,A39,'دفتر اليومية'!E:E,"مبيعات كاش") +SUMIFS('دفتر اليومية'!K:K,'دفتر اليومية'!AC:AC,A39,'دفتر اليومية'!E:E,"مبيعات اجل") -> 0 | C39: =SUMIFS('دفتر اليومية'!K:K, 'دفتر اليومية'!E:E, "مصروفات", 'دفتر اليومية'!AC:AC, Dashboard!A39) -> 0 | D39: =SUMIFS('دفتر اليومية'!K:K, 'دفتر اليومية'!E:E, "مشتريات", 'دفتر اليومية'!AC:AC, Dashboard!A39) -> 0 | E39: =B39-C39-D39 -> 0
A40: May | B40: =SUMIFS('دفتر اليومية'!K:K,'دفتر اليومية'!AC:AC,A40,'دفتر اليومية'!E:E,"مبيعات كاش") +SUMIFS('دفتر اليومية'!K:K,'دفتر اليومية'!AC:AC,A40,'دفتر اليومية'!E:E,"مبيعات اجل") -> 0 | C40: =SUMIFS('دفتر اليومية'!K:K, 'دفتر اليومية'!E:E, "مصروفات", 'دفتر اليومية'!AC:AC, Dashboard!A40) -> 0 | D40: =SUMIFS('دفتر اليومية'!K:K, 'دفتر اليومية'!E:E, "مشتريات", 'دفتر اليومية'!AC:AC, Dashboard!A40) -> 2000 | E40: =B40-C40-D40 -> -2000
A41: Jun | B41: =SUMIFS('دفتر اليومية'!K:K,'دفتر اليومية'!AC:AC,A41,'دفتر اليومية'!E:E,"مبيعات كاش") +SUMIFS('دفتر اليومية'!K:K,'دفتر اليومية'!AC:AC,A41,'دفتر اليومية'!E:E,"مبيعات اجل") -> 16550 | C41: =SUMIFS('دفتر اليومية'!K:K, 'دفتر اليومية'!E:E, "مصروفات", 'دفتر اليومية'!AC:AC, Dashboard!A41) -> 0 | D41: =SUMIFS('دفتر اليومية'!K:K, 'دفتر اليومية'!E:E, "مشتريات", 'دفتر اليومية'!AC:AC, Dashboard!A41) -> 0 | E41: =B41-C41-D41 -> 16550
A42: Jul | B42: =SUMIFS('دفتر اليومية'!K:K,'دفتر اليومية'!AC:AC,A42,'دفتر اليومية'!E:E,"مبيعات كاش") +SUMIFS('دفتر اليومية'!K:K,'دفتر اليومية'!AC:AC,A42,'دفتر اليومية'!E:E,"مبيعات اجل") -> 528080 | C42: =SUMIFS('دفتر اليومية'!K:K, 'دفتر اليومية'!E:E, "مصروفات", 'دفتر اليومية'!AC:AC, Dashboard!A42) -> 0 | D42: =SUMIFS('دفتر اليومية'!K:K, 'دفتر اليومية'!E:E, "مشتريات", 'دفتر اليومية'!AC:AC, Dashboard!A42) -> 0 | E42: =B42-C42-D42 -> 528080
A43: Aug | B43: =SUMIFS('دفتر اليومية'!K:K,'دفتر اليومية'!AC:AC,A43,'دفتر اليومية'!E:E,"مبيعات كاش") +SUMIFS('دفتر اليومية'!K:K,'دفتر اليومية'!AC:AC,A43,'دفتر اليومية'!E:E,"مبيعات اجل") -> 12225 | C43: =SUMIFS('دفتر اليومية'!K:K, 'دفتر اليومية'!E:E, "مصروفات", 'دفتر اليومية'!AC:AC, Dashboard!A43) -> 1000 | D43: =SUMIFS('دفتر اليومية'!K:K, 'دفتر اليومية'!E:E, "مشتريات", 'دفتر اليومية'!AC:AC, Dashboard!A43) -> 750 | E43: =B43-C43-D43 -> 10475
A44: Sep | B44: =SUMIFS('دفتر اليومية'!K:K,'دفتر اليومية'!AC:AC,A44,'دفتر اليومية'!E:E,"مبيعات كاش") +SUMIFS('دفتر اليومية'!K:K,'دفتر اليومية'!AC:AC,A44,'دفتر اليومية'!E:E,"مبيعات اجل") -> 0 | C44: =SUMIFS('دفتر اليومية'!K:K, 'دفتر اليومية'!E:E, "مصروفات", 'دفتر اليومية'!AC:AC, Dashboard!A44) -> 0 | D44: =SUMIFS('دفتر اليومية'!K:K, 'دفتر اليومية'!E:E, "مشتريات", 'دفتر اليومية'!AC:AC, Dashboard!A44) -> 0 | E44: =B44-C44-D44 -> 0
A45: Oct | B45: =SUMIFS('دفتر اليومية'!K:K,'دفتر اليومية'!AC:AC,A45,'دفتر اليومية'!E:E,"مبيعات كاش") +SUMIFS('دفتر اليومية'!K:K,'دفتر اليومية'!AC:AC,A45,'دفتر اليومية'!E:E,"مبيعات اجل") -> 0 | C45: =SUMIFS('دفتر اليومية'!K:K, 'دفتر اليومية'!E:E, "مصروفات", 'دفتر اليومية'!AC:AC, Dashboard!A45) -> 0 | D45: =SUMIFS('دفتر اليومية'!K:K, 'دفتر اليومية'!E:E, "مشتريات", 'دفتر اليومية'!AC:AC, Dashboard!A45) -> 0 | E45: =B45-C45-D45 -> 0
A46: Nov | B46: =SUMIFS('دفتر اليومية'!K:K,'دفتر اليومية'!AC:AC,A46,'دفتر اليومية'!E:E,"مبيعات كاش") +SUMIFS('دفتر اليومية'!K:K,'دفتر اليومية'!AC:AC,A46,'دفتر اليومية'!E:E,"مبيعات اجل") -> 0 | C46: =SUMIFS('دفتر اليومية'!K:K, 'دفتر اليومية'!E:E, "مصروفات", 'دفتر اليومية'!AC:AC, Dashboard!A46) -> 0 | D46: =SUMIFS('دفتر اليومية'!K:K, 'دفتر اليومية'!E:E, "مشتريات", 'دفتر اليومية'!AC:AC, Dashboard!A46) -> 0 | E46: =B46-C46-D46 -> 0
A47: Dec | B47: =SUMIFS('دفتر اليومية'!K:K,'دفتر اليومية'!AC:AC,A47,'دفتر اليومية'!E:E,"مبيعات كاش") +SUMIFS('دفتر اليومية'!K:K,'دفتر اليومية'!AC:AC,A47,'دفتر اليومية'!E:E,"مبيعات اجل") -> 0 | C47: =SUMIFS('دفتر اليومية'!K:K, 'دفتر اليومية'!E:E, "مصروفات", 'دفتر اليومية'!AC:AC, Dashboard!A47) -> 0 | D47: =SUMIFS('دفتر اليومية'!K:K, 'دفتر اليومية'!E:E, "مشتريات", 'دفتر اليومية'!AC:AC, Dashboard!A47) -> 0 | E47: =B47-C47-D47 -> 0
A48: الاجمالى | B48: =SUM(B36:B47) -> 556855 | C48: =SUM(C36:C47) -> 1000 | D48: =SUM(D36:D47) -> 2750 | E48: =SUM(E36:E47) -> 553105
A50: التصنيف | B50: عدد المبيعات | C50: أجمالى الدخل | D50: صافى الربح | E50: %
A51: {=_xlfn.UNIQUE(_xlfn._xlws.FILTER('تحليل مبيعات'!F10:F3996, 'تحليل مبيعات'!F10:F3996<>""))} -> بطارية | B51: =SUMIFS('تحليل مبيعات'!H:H,'تحليل مبيعات'!F:F,A51) -> 35 | C51: =SUMIFS('تحليل مبيعات'!L:L,'تحليل مبيعات'!F:F,A51) -> 68650 | D51: =SUMIFS('تحليل مبيعات'!M:M,'تحليل مبيعات'!F:F,A51) -> 55945 | E51: =D51/D54 -> 0.12174608
A52: كاوتش | B52: =SUMIFS('تحليل مبيعات'!H:H,'تحليل مبيعات'!F:F,A52) -> 94 | C52: =SUMIFS('تحليل مبيعات'!L:L,'تحليل مبيعات'!F:F,A52) -> 336100 | D52: =SUMIFS('تحليل مبيعات'!M:M,'تحليل مبيعات'!F:F,A52) -> 323570 | E52: =D52/D54 -> 0.70414474
A53: قطع غيار | B53: =SUMIFS('تحليل مبيعات'!H:H,'تحليل مبيعات'!F:F,A53) -> 508 | C53: =SUMIFS('تحليل مبيعات'!L:L,'تحليل مبيعات'!F:F,A53) -> 154280 | D53: =SUMIFS('تحليل مبيعات'!M:M,'تحليل مبيعات'!F:F,A53) -> 80007 | E53: =D53/D54 -> 0.17410918
A54: المجموع | B54: =SUM(B51:B53) -> 637 | C54: =SUM(C51:C53) -> 559030 | D54: =SUM(D51:D53) -> 459522 | E54: =SUM(E51:E53) -> 1

Sheet ⁠حسابات عملاء
A1: اسم العميل | B1: إجمالي المبيعات الآجل | C1: إجمالي المسدد | D1: المتبقي | P1: 3 | AP1: Row Labels | AQ1: إجمالي المسدد | AR1: إجمالي المبيعات الآجل. | AS1: المتبقي
A2: {=_xlfn.UNIQUE(_xlfn._xlws.FILTER('دفتر اليومية'!H:H, 'دفتر اليومية'!E:E="مبيعات اجل"))} -> Client 19 | B2: =SUMIFS('دفتر اليومية'!K:K, 'دفتر اليومية'!H:H, A2, 'دفتر اليومية'!E:E, "مبيعات اجل") -> 44550 | C2: =SUMIFS('دفتر اليومية'!L:L, 'دفتر اليومية'!H:H, A2, 'دفتر اليومية'!E:E, "مبيعات اجل") -> 0 | D2: =B2-C2 -> 44550 | AP2: احمد ابوحطب | AQ2: 0 | AR2: 9550 | AS2: 9550
A3: Client 15 | B3: =SUMIFS('دفتر اليومية'!K:K, 'دفتر اليومية'!H:H, A3, 'دفتر اليومية'!E:E, "مبيعات اجل") -> 66550 | C3: =SUMIFS('دفتر اليومية'!L:L, 'دفتر اليومية'!H:H, A3, 'دفتر اليومية'!E:E, "مبيعات اجل") -> 0 | D3: =B3-C3 -> 66550 | AP3: احمد سعيد | AQ3: 0 | AR3: 2850 | AS3: 2850
A4: Client 10 | B4: =SUMIFS('دفتر اليومية'!K:K, 'دفتر اليومية'!H:H, A4, 'دفتر اليومية'!E:E, "مبيعات اجل") -> 24350 | C4: =SUMIFS('دفتر اليومية'!L:L, 'دفتر اليومية'!H:H, A4, 'دفتر اليومية'!E:E, "مبيعات اجل") -> 0 | D4: =B4-C4 -> 24350 | AP4: احمد عبد الله شبين | AQ4: 0 | AR4: 18450 | AS4: 18450
A5: Client 20 | B5: =SUMIFS('دفتر اليومية'!K:K, 'دفتر اليومية'!H:H, A5, 'دفتر اليومية'!E:E, "مبيعات اجل") -> 13150 | C5: =SUMIFS('دفتر اليومية'!L:L, 'دفتر اليومية'!H:H, A5, 'دفتر اليومية'!E:E, "مبيعات اجل") -> 0 | D5: =B5-C5 -> 13150 | AP5: احمد ماهر | AQ5: 0 | AR5: 3050 | AS5: 3050
A6: Client 14 | B6: =SUMIFS('دفتر اليومية'!K:K, 'دفتر اليومية'!H:H, A6, 'دفتر اليومية'!E:E, "مبيعات اجل") -> 7100 | C6: =SUMIFS('دفتر اليومية'!L:L, 'دفتر اليومية'!H:H, A6, 'دفتر اليومية'!E:E, "مبيعات اجل") -> 0 | D6: =B6-C6 -> 7100 | AP6: الحاج رفعت | AQ6: 0 | AR6: 7950 | AS6: 7950
A7: Client 17 | B7: =SUMIFS('دفتر اليومية'!K:K, 'دفتر اليومية'!H:H, A7, 'دفتر اليومية'!E:E, "مبيعات اجل") -> 8000 | C7: =SUMIFS('دفتر اليومية'!L:L, 'دفتر اليومية'!H:H, A7, 'دفتر اليومية'!E:E, "مبيعات اجل") -> 0 | D7: =B7-C7 -> 8000 | AP7: زياد وحيد | AQ7: 0 | AR7: 1950 | AS7: 1950
A8: Client 18 | B8: =SUMIFS('دفتر اليومية'!K:K, 'دفتر اليومية'!H:H, A8, 'دفتر اليومية'!E:E, "مبيعات اجل") -> 6700 | C8: =SUMIFS('دفتر اليومية'!L:L, 'دفتر اليومية'!H:H, A8, 'دفتر اليومية'!E:E, "مبيعات اجل") -> 0 | D8: =B8-C8 -> 6700 | AP8: سيد الزهار | AQ8: 0 | AR8: 5150 | AS8: 5150
A9: Client 11 | B9: =SUMIFS('دفتر اليومية'!K:K, 'دفتر اليومية'!H:H, A9, 'دفتر اليومية'!E:E, "مبيعات اجل") -> 7950 | C9: =SUMIFS('دفتر اليومية'!L:L, 'دفتر اليومية'!H:H, A9, 'دفتر اليومية'!E:E, "مبيعات اجل") -> 0 | D9: =B9-C9 -> 7950 | AP9: سيد حمائى | AQ9: 0 | AR9: 20000 | AS9: 20000
A10: Client 8 | B10: =SUMIFS('دفتر اليومية'!K:K, 'دفتر اليومية'!H:H, A10, 'دفتر اليومية'!E:E, "مبيعات اجل") -> 9550 | C10: =SUMIFS('دفتر اليومية'!L:L, 'دفتر اليومية'!H:H, A10, 'دفتر اليومية'!E:E, "مبيعات اجل") -> 0 | D10: =B10-C10 -> 9550 | AP10: سيد كشرى | AQ10: 0 | AR10: 33550 | AS10: 33550
B11: =SUMIFS('دفتر اليومية'!K:K, 'دفتر اليومية'!H:H, A11, 'دفتر اليومية'!E:E, "مبيعات اجل") -> 0 | C11: =SUMIFS('دفتر اليومية'!L:L, 'دفتر اليومية'!H:H, A11, 'دفتر اليومية'!E:E, "مبيعات اجل") -> 0 | D11: =B11-C11 -> 0 | AP11: عادل نظير | AQ11: 0 | AR11: 7950 | AS11: 7950
B12: =SUMIFS('دفتر اليومية'!K:K, 'دفتر اليومية'!H:H, A12, 'دفتر اليومية'!E:E, "مبيعات اجل") -> 0 | C12: =SUMIFS('دفتر اليومية'!L:L, 'دفتر اليومية'!H:H, A12, 'دفتر اليومية'!E:E, "مبيعات اجل") -> 0 | D12: =B12-C12 -> 0 | AP12: عم عجيبة | AQ12: 0 | AR12: 5050 | AS12: 5050
B13: =SUMIFS('دفتر اليومية'!K:K, 'دفتر اليومية'!H:H, A13, 'دفتر اليومية'!E:E, "مبيعات اجل") -> 0 | C13: =SUMIFS('دفتر اليومية'!L:L, 'دفتر اليومية'!H:H, A13, 'دفتر اليومية'!E:E, "مبيعات اجل") -> 0 | D13: =B13-C13 -> 0 | AP13: كريم العجل | AQ13: 0 | AR13: 8000 | AS13: 8000
B14: =SUMIFS('دفتر اليومية'!K:K, 'دفتر اليومية'!H:H, A14, 'دفتر اليومية'!E:E, "مبيعات اجل") -> 0 | C14: =SUMIFS('دفتر اليومية'!L:L, 'دفتر اليومية'!H:H, A14, 'دفتر اليومية'!E:E, "مبيعات اجل") -> 0 | D14: =B14-C14 -> 0 | AP14: محمد اشرف | AQ14: 0 | AR14: 17150 | AS14: 17150
B15: =SUMIFS('دفتر اليومية'!K:K, 'دفتر اليومية'!H:H, A15, 'دفتر اليومية'!E:E, "مبيعات اجل") -> 0 | C15: =SUMIFS('دفتر اليومية'!L:L, 'دفتر اليومية'!H:H, A15, 'دفتر اليومية'!E:E, "مبيعات اجل") -> 0 | D15: =B15-C15 -> 0 | AP15: محمد ذكى | AQ15: 0 | AR15: 4200 | AS15: 4200
B16: =SUMIFS('دفتر اليومية'!K:K, 'دفتر اليومية'!H:H, A16, 'دفتر اليومية'!E:E, "مبيعات اجل") -> 0 | C16: =SUMIFS('دفتر اليومية'!L:L, 'دفتر اليومية'!H:H, A16, 'دفتر اليومية'!E:E, "مبيعات اجل") -> 0 | D16: =B16-C16 -> 0 | AP16: محمد راس | AQ16: 0 | AR16: 9750 | AS16: 9750
B17: =SUMIFS('دفتر اليومية'!K:K, 'دفتر اليومية'!H:H, A17, 'دفتر اليومية'!E:E, "مبيعات اجل") -> 0 | C17: =SUMIFS('دفتر اليومية'!L:L, 'دفتر اليومية'!H:H, A17, 'دفتر اليومية'!E:E, "مبيعات اجل") -> 0 | D17: =B17-C17 -> 0 | AP17: محمود عطيه | AQ17: 0 | AR17: 17650 | AS17: 17650
B18: =SUMIFS('دفتر اليومية'!K:K, 'دفتر اليومية'!H:H, A18, 'دفتر اليومية'!E:E, "مبيعات اجل") -> 0 | C18: =SUMIFS('دفتر اليومية'!L:L, 'دفتر اليومية'!H:H, A18, 'دفتر اليومية'!E:E, "مبيعات اجل") -> 0 | D18: =B18-C18 -> 0 | AP18: ممدوح خيشة | AQ18: 0 | AR18: 3800 | AS18: 3800
B19: =SUMIFS('دفتر اليومية'!K:K, 'دفتر اليومية'!H:H, A19, 'دفتر اليومية'!E:E, "مبيعات اجل") -> 0 | C19: =SUMIFS('دفتر اليومية'!L:L, 'دفتر اليومية'!H:H, A19, 'دفتر اليومية'!E:E, "مبيعات اجل") -> 0 | D19: =B19-C19 -> 0 | AP19: مؤمن الميكا | AQ19: 0 | AR19: 2500 | AS19: 2500
B20: =SUMIFS('دفتر اليومية'!K:K, 'دفتر اليومية'!H:H, A20, 'دفتر اليومية'!E:E, "مبيعات اجل") -> 0 | C20: =SUMIFS('دفتر اليومية'!L:L, 'دفتر اليومية'!H:H, A20, 'دفتر اليومية'!E:E, "مبيعات اجل") -> 0 | D20: =B20-C20 -> 0 | AP20: ميدو بسيونى | AQ20: 0 | AR20: 9350 | AS20: 9350
B21: =SUMIFS('دفتر اليومية'!K:K, 'دفتر اليومية'!H:H, A21, 'دفتر اليومية'!E:E, "مبيعات اجل") -> 0 | C21: =SUMIFS('دفتر اليومية'!L:L, 'دفتر اليومية'!H:H, A21, 'دفتر اليومية'!E:E, "مبيعات اجل") -> 0 | D21: =B21-C21 -> 0 | AP21: (blank) | AQ21: 0 | AR21: 0 | AS21: 0
B22: =SUMIFS('دفتر اليومية'!K:K, 'دفتر اليومية'!H:H, A22, 'دفتر اليومية'!E:E, "مبيعات اجل") -> 0 | C22: =SUMIFS('دفتر اليومية'!L:L, 'دفتر اليومية'!H:H, A22, 'دفتر اليومية'!E:E, "مبيعات اجل") -> 0 | D22: =B22-C22 -> 0 | AP22: Grand Total | AQ22: 0 | AR22: 187900 | AS22: 187900
B23: =SUMIFS('دفتر اليومية'!K:K, 'دفتر اليومية'!H:H, A23, 'دفتر اليومية'!E:E, "مبيعات اجل") -> 0 | C23: =SUMIFS('دفتر اليومية'!L:L, 'دفتر اليومية'!H:H, A23, 'دفتر اليومية'!E:E, "مبيعات اجل") -> 0 | D23: =B23-C23 -> 0
B24: =SUMIFS('دفتر اليومية'!K:K, 'دفتر اليومية'!H:H, A24, 'دفتر اليومية'!E:E, "مبيعات اجل") -> 0 | C24: =SUMIFS('دفتر اليومية'!L:L, 'دفتر اليومية'!H:H, A24, 'دفتر اليومية'!E:E, "مبيعات اجل") -> 0 | D24: =B24-C24 -> 0
B25: =SUMIFS('دفتر اليومية'!K:K, 'دفتر اليومية'!H:H, A25, 'دفتر اليومية'!E:E, "مبيعات اجل") -> 0 | C25: =SUMIFS('دفتر اليومية'!L:L, 'دفتر اليومية'!H:H, A25, 'دفتر اليومية'!E:E, "مبيعات اجل") -> 0 | D25: =B25-C25 -> 0
B26: =SUMIFS('دفتر اليومية'!K:K, 'دفتر اليومية'!H:H, A26, 'دفتر اليومية'!E:E, "مبيعات اجل") -> 0 | C26: =SUMIFS('دفتر اليومية'!L:L, 'دفتر اليومية'!H:H, A26, 'دفتر اليومية'!E:E, "مبيعات اجل") -> 0 | D26: =B26-C26 -> 0
B27: =SUMIFS('دفتر اليومية'!K:K, 'دفتر اليومية'!H:H, A27, 'دفتر اليومية'!E:E, "مبيعات اجل") -> 0 | C27: =SUMIFS('دفتر اليومية'!L:L, 'دفتر اليومية'!H:H, A27, 'دفتر اليومية'!E:E, "مبيعات اجل") -> 0 | D27: =B27-C27 -> 0
B28: =SUMIFS('دفتر اليومية'!K:K, 'دفتر اليومية'!H:H, A28, 'دفتر اليومية'!E:E, "مبيعات اجل") -> 0 | C28: =SUMIFS('دفتر اليومية'!L:L, 'دفتر اليومية'!H:H, A28, 'دفتر اليومية'!E:E, "مبيعات اجل") -> 0 | D28: =B28-C28 -> 0
B29: =SUMIFS('دفتر اليومية'!K:K, 'دفتر اليومية'!H:H, A29, 'دفتر اليومية'!E:E, "مبيعات اجل") -> 0 | C29: =SUMIFS('دفتر اليومية'!L:L, 'دفتر اليومية'!H:H, A29, 'دفتر اليومية'!E:E, "مبيعات اجل") -> 0 | D29: =B29-C29 -> 0
B30: =SUMIFS('دفتر اليومية'!K:K, 'دفتر اليومية'!H:H, A30, 'دفتر اليومية'!E:E, "مبيعات اجل") -> 0 | C30: =SUMIFS('دفتر اليومية'!L:L, 'دفتر اليومية'!H:H, A30, 'دفتر اليومية'!E:E, "مبيعات اجل") -> 0 | D30: =B30-C30 -> 0
B31: =SUMIFS('دفتر اليومية'!K:K, 'دفتر اليومية'!H:H, A31, 'دفتر اليومية'!E:E, "مبيعات اجل") -> 0 | C31: =SUMIFS('دفتر اليومية'!L:L, 'دفتر اليومية'!H:H, A31, 'دفتر اليومية'!E:E, "مبيعات اجل") -> 0 | D31: =B31-C31 -> 0
B32: =SUMIFS('دفتر اليومية'!K:K, 'دفتر اليومية'!H:H, A32, 'دفتر اليومية'!E:E, "مبيعات اجل") -> 0 | C32: =SUMIFS('دفتر اليومية'!L:L, 'دفتر اليومية'!H:H, A32, 'دفتر اليومية'!E:E, "مبيعات اجل") -> 0 | D32: =B32-C32 -> 0
B33: =SUMIFS('دفتر اليومية'!K:K, 'دفتر اليومية'!H:H, A33, 'دفتر اليومية'!E:E, "مبيعات اجل") -> 0 | C33: =SUMIFS('دفتر اليومية'!L:L, 'دفتر اليومية'!H:H, A33, 'دفتر اليومية'!E:E, "مبيعات اجل") -> 0 | D33: =B33-C33 -> 0
B34: =SUMIFS('دفتر اليومية'!K:K, 'دفتر اليومية'!H:H, A34, 'دفتر اليومية'!E:E, "مبيعات اجل") -> 0 | C34: =SUMIFS('دفتر اليومية'!L:L, 'دفتر اليومية'!H:H, A34, 'دفتر اليومية'!E:E, "مبيعات اجل") -> 0 | D34: =B34-C34 -> 0
... B1169: =SUMIFS('دفتر اليومية'!K:K, 'دفتر اليومية'!H:H, A1169, 'دفتر اليومية'!E:E, "مبيعات اجل") -> 0 | C1169: =SUMIFS('دفتر اليومية'!L:L, 'دفتر اليومية'!H:H, A1169, 'دفتر اليومية'!E:E, "مبيعات اجل") -> 0 | D1169: =B1169-C1169 -> 0

Sheet حركة المخزن
D2: قطع غيار
D3: كاوتش
D4: جنط
D5: بطارية | L5: =SUM(L8:L1117) -> 110375
B6: الصنف | C6: كود الصنف | D6: التصنيف | E6: الرصيد الافتتاحي | G6: المشتريات | I6: المبيعات | K6: الرصيد الحالي | Q6: الصنف | R6: Jan | S6: Feb | T6: Mar | U6: Apr | V6: May | W6: Jun | X6: Jul | Y6: Aug | Z6: Sep | AA6: Oct | AB6: Nov | AC6: Dec | AD6: الاجمالى
E7: الكمية | F7: التكلفة | G7: الكمية | H7: التكلفة | I7: الكمية | J7: التكلفة | K7: الكمية | L7: التكلفة | M7: كمية أعادة الطلب | N7: الحالة | O7: تكلفة الوحدة | Q7: {=_xlfn.UNIQUE(_xlfn._xlws.FILTER('تحليل مبيعات'!C10:C3996, 'تحليل مبيعات'!C10:C3996<>""))} -> بطارية كلورايد 70 معكوسة | R7: =SUMIFS('تحليل مبيعات'!H:H,'تحليل مبيعات'!C:C,'حركة المخزن'!Q7,'تحليل مبيعات'!W:W,'حركة المخزن'!$R$6) -> 0 | S7: =SUMIFS('تحليل مبيعات'!H:H,'تحليل مبيعات'!C:C,'حركة المخزن'!Q7,'تحليل مبيعات'!W:W,'حركة المخزن'!$S$6) -> 0 | T7: =SUMIFS('تحليل مبيعات'!H:H,'تحليل مبيعات'!C:C,'حركة المخزن'!Q7,'تحليل مبيعات'!W:W,'حركة المخزن'!$T$6) -> 0 | U7: =SUMIFS('تحليل مبيعات'!H:H,'تحليل مبيعات'!C:C,'حركة المخزن'!Q7,'تحليل مبيعات'!W:W,'حركة المخزن'!$U$6) -> 0 | V7: =SUMIFS('تحليل مبيعات'!H:H,'تحليل مبيعات'!C:C,'حركة المخزن'!Q7,'تحليل مبيعات'!W:W,'حركة المخزن'!$V$6) -> 0 | W7: =SUMIFS('تحليل مبيعات'!H:H,'تحليل مبيعات'!C:C,'حركة المخزن'!Q7,'تحليل مبيعات'!W:W,'حركة المخزن'!$W$6) -> 0 | X7: =SUMIFS('تحليل مبيعات'!H:H,'تحليل مبيعات'!C:C,'حركة المخزن'!Q7,'تحليل مبيعات'!W:W,'حركة المخزن'!$X$6) -> 1 | Y7: =SUMIFS('تحليل مبيعات'!H:H,'تحليل مبيعات'!C:C,'حركة المخزن'!Q7,'تحليل مبيعات'!W:W,'حركة المخزن'!$Y$6) -> 0 | Z7: =SUMIFS('تحليل مبيعات'!H:H,'تحليل مبيعات'!C:C,'حركة المخزن'!Q7,'تحليل مبيعات'!W:W,'حركة المخزن'!$Z$6) -> 0 | AA7: =SUMIFS('تحليل مبيعات'!H:H,'تحليل مبيعات'!C:C,'حركة المخزن'!Q7,'تحليل مبيعات'!W:W,'حركة المخزن'!$AA$6) -> 0 | AB7: =SUMIFS('تحليل مبيعات'!H:H,'تحليل مبيعات'!C:C,'حركة المخزن'!Q7,'تحليل مبيعات'!W:W,'حركة المخزن'!$AB$6) -> 0 | AC7: =SUMIFS('تحليل مبيعات'!H:H,'تحليل مبيعات'!C:C,'حركة المخزن'!Q7,'تحليل مبيعات'!W:W,'حركة المخزن'!$AC$6) -> 0 | AD7: =SUM(R7:AC7) -> 1
B8: اكسليرا 13/175/70 | C8: C0001 | D8: كاوتش | E8: 5 | F8: 1000 | G8: 0 | H8: 0 | I8: =IFERROR(IF(SUMIF('تحليل مبيعات'!C:C, 'حركة المخزن'!B8, 'تحليل مبيعات'!H:H)=0,"",SUMIF('تحليل مبيعات'!C:C, 'حركة المخزن'!B8, 'تحليل مبيعات'!H:H)),"") -> 5 | J8: =IFERROR(IF(SUMIF('تحليل مبيعات'!C:C, 'حركة المخزن'!B8, 'تحليل مبيعات'!L:L)=0,"",SUMIF('تحليل مبيعات'!C:C, 'حركة المخزن'!B8, 'تحليل مبيعات'!L:L)),"") -> 8850 | K8: =IFERROR(E8+G8-I8,"") -> 0 | L8: =IFERROR(F8+H8-J8,"") -> -7850 | M8: 5 | N8: =IF(K8<M8,"أعادة الطلب","يوجد رصيد كافى") -> أعادة الطلب | O8: 100 | Q8: اكسليرا 13/175/70 | R8: =SUMIFS('تحليل مبيعات'!H:H,'تحليل مبيعات'!C:C,'حركة المخزن'!Q8,'تحليل مبيعات'!W:W,'حركة المخزن'!$R$6) -> 0 | S8: =SUMIFS('تحليل مبيعات'!H:H,'تحليل مبيعات'!C:C,'حركة المخزن'!Q8,'تحليل مبيعات'!W:W,'حركة المخزن'!$S$6) -> 0 | T8: =SUMIFS('تحليل مبيعات'!H:H,'تحليل مبيعات'!C:C,'حركة المخزن'!Q8,'تحليل مبيعات'!W:W,'حركة المخزن'!$T$6) -> 0 | U8: =SUMIFS('تحليل مبيعات'!H:H,'تحليل مبيعات'!C:C,'حركة المخزن'!Q8,'تحليل مبيعات'!W:W,'حركة المخزن'!$U$6) -> 0 | V8: =SUMIFS('تحليل مبيعات'!H:H,'تحليل مبيعات'!C:C,'حركة المخزن'!Q8,'تحليل مبيعات'!W:W,'حركة المخزن'!$V$6) -> 0 | W8: =SUMIFS('تحليل مبيعات'!H:H,'تحليل مبيعات'!C:C,'حركة المخزن'!Q8,'تحليل مبيعات'!W:W,'حركة المخزن'!$W$6) -> 1 | X8: =SUMIFS('تحليل مبيعات'!H:H,'تحليل مبيعات'!C:C,'حركة المخزن'!Q8,'تحليل مبيعات'!W:W,'حركة المخزن'!$X$6) -> 4 | Y8: =SUMIFS('تحليل مبيعات'!H:H,'تحليل مبيعات'!C:C,'حركة المخزن'!Q8,'تحليل مبيعات'!W:W,'حركة المخزن'!$Y$6) -> 0 | Z8: =SUMIFS('تحليل مبيعات'!H:H,'تحليل مبيعات'!C:C,'حركة المخزن'!Q8,'تحليل مبيعات'!W:W,'حركة المخزن'!$Z$6) -> 0 | AA8: =SUMIFS('تحليل مبيعات'!H:H,'تحليل مبيعات'!C:C,'حركة المخزن'!Q8,'تحليل مبيعات'!W:W,'حركة المخزن'!$AA$6) -> 0 | AB8: =SUMIFS('تحليل مبيعات'!H:H,'تحليل مبيعات'!C:C,'حركة المخزن'!Q8,'تحليل مبيعات'!W:W,'حركة المخزن'!$AB$6) -> 0 | AC8: =SUMIFS('تحليل مبيعات'!H:H,'تحليل مبيعات'!C:C,'حركة المخزن'!Q8,'تحليل مبيعات'!W:W,'حركة المخزن'!$AC$6) -> 0 | AD8: =SUM(R8:AC8) -> 5
B9: اكسليرا 15/195/65 | C9: C0002 | D9: كاوتش | E9: 5 | F9: 1000 | G9: 0 | H9: 0 | I9: =IFERROR(IF(SUMIF('تحليل مبيعات'!C:C, 'حركة المخزن'!B9, 'تحليل مبيعات'!H:H)=0,"",SUMIF('تحليل مبيعات'!C:C, 'حركة المخزن'!B9, 'تحليل مبيعات'!H:H)),"") -> 2 | J9: =IFERROR(IF(SUMIF('تحليل مبيعات'!C:C, 'حركة المخزن'!B9, 'تحليل مبيعات'!L:L)=0,"",SUMIF('تحليل مبيعات'!C:C, 'حركة المخزن'!B9, 'تحليل مبيعات'!L:L)),"") -> 4500 | K9: =IFERROR(E9+G9-I9,"") -> 3 | L9: =IFERROR(F9+H9-J9,"") -> -3500 | M9: 5 | N9: =IF(K9<M9,"أعادة الطلب","يوجد رصيد كافى") -> أعادة الطلب | O9: 200 | Q9: بلف كتينة | R9: =SUMIFS('تحليل مبيعات'!H:H,'تحليل مبيعات'!C:C,'حركة المخزن'!Q9,'تحليل مبيعات'!W:W,'حركة المخزن'!$R$6) -> 0 | S9: =SUMIFS('تحليل مبيعات'!H:H,'تحليل مبيعات'!C:C,'حركة المخزن'!Q9,'تحليل مبيعات'!W:W,'حركة المخزن'!$S$6) -> 0 | T9: =SUMIFS('تحليل مبيعات'!H:H,'تحليل مبيعات'!C:C,'حركة المخزن'!Q9,'تحليل مبيعات'!W:W,'حركة المخزن'!$T$6) -> 0 | U9: =SUMIFS('تحليل مبيعات'!H:H,'تحليل مبيعات'!C:C,'حركة المخزن'!Q9,'تحليل مبيعات'!W:W,'حركة المخزن'!$U$6) -> 0 | V9: =SUMIFS('تحليل مبيعات'!H:H,'تحليل مبيعات'!C:C,'حركة المخزن'!Q9,'تحليل مبيعات'!W:W,'حركة المخزن'!$V$6) -> 0 | W9: =SUMIFS('تحليل مبيعات'!H:H,'تحليل مبيعات'!C:C,'حركة المخزن'!Q9,'تحليل مبيعات'!W:W,'حركة المخزن'!$W$6) -> 0 | X9: =SUMIFS('تحليل مبيعات'!H:H,'تحليل مبيعات'!C:C,'حركة المخزن'!Q9,'تحليل مبيعات'!W:W,'حركة المخزن'!$X$6) -> 17 | Y9: =SUMIFS('تحليل مبيعات'!H:H,'تحليل مبيعات'!C:C,'حركة المخزن'!Q9,'تحليل مبيعات'!W:W,'حركة المخزن'!$Y$6) -> 0 | Z9: =SUMIFS('تحليل مبيعات'!H:H,'تحليل مبيعات'!C:C,'حركة المخزن'!Q9,'تحليل مبيعات'!W:W,'حركة المخزن'!$Z$6) -> 0 | AA9: =SUMIFS('تحليل مبيعات'!H:H,'تحليل مبيعات'!C:C,'حركة المخزن'!Q9,'تحليل مبيعات'!W:W,'حركة المخزن'!$AA$6) -> 0 | AB9: =SUMIFS('تحليل مبيعات'!H:H,'تحليل مبيعات'!C:C,'حركة المخزن'!Q9,'تحليل مبيعات'!W:W,'حركة المخزن'!$AB$6) -> 0 | AC9: =SUMIFS('تحليل مبيعات'!H:H,'تحليل مبيعات'!C:C,'حركة المخزن'!Q9,'تحليل مبيعات'!W:W,'حركة المخزن'!$AC$6) -> 0 | AD9: =SUM(R9:AC9) -> 17
B10: NOZA ECO 15/185/65 كاوتش سومو اكينا صينى | C10: C0003 | D10: كاوتش | E10: 5 | F10: 1000 | G10: 0 | H10: 0 | I10: =IFERROR(IF(SUMIF('تحليل مبيعات'!C:C, 'حركة المخزن'!B10, 'تحليل مبيعات'!H:H)=0,"",SUMIF('تحليل مبيعات'!C:C, 'حركة المخزن'!B10, 'تحليل مبيعات'!H:H)),"") -> 6 | J10: =IFERROR(IF(SUMIF('تحليل مبيعات'!C:C, 'حركة المخزن'!B10, 'تحليل مبيعات'!L:L)=0,"",SUMIF('تحليل مبيعات'!C:C, 'حركة المخزن'!B10, 'تحليل مبيعات'!L:L)),"") -> 11100 | K10: =IFERROR(E10+G10-I10,"") -> -1 | L10: =IFERROR(F10+H10-J10,"") -> -10100 | M10: 5 | N10: =IF(K10<M10,"أعادة الطلب","يوجد رصيد كافى") -> أعادة الطلب | O10: 100 | Q10: مروحة تويوتا عريضة | R10: =SUMIFS('تحليل مبيعات'!H:H,'تحليل مبيعات'!C:C,'حركة المخزن'!Q10,'تحليل مبيعات'!W:W,'حركة المخزن'!$R$6) -> 0 | S10: =SUMIFS('تحليل مبيعات'!H:H,'تحليل مبيعات'!C:C,'حركة المخزن'!Q10,'تحليل مبيعات'!W:W,'حركة المخزن'!$S$6) -> 0 | T10: =SUMIFS('تحليل مبيعات'!H:H,'تحليل مبيعات'!C:C,'حركة المخزن'!Q10,'تحليل مبيعات'!W:W,'حركة المخزن'!$T$6) -> 0 | U10: =SUMIFS('تحليل مبيعات'!H:H,'تحليل مبيعات'!C:C,'حركة المخزن'!Q10,'تحليل مبيعات'!W:W,'حركة المخزن'!$U$6) -> 0 | V10: =SUMIFS('تحليل مبيعات'!H:H,'تحليل مبيعات'!C:C,'حركة المخزن'!Q10,'تحليل مبيعات'!W:W,'حركة المخزن'!$V$6) -> 0 | W10: =SUMIFS('تحليل مبيعات'!H:H,'تحليل مبيعات'!C:C,'حركة المخزن'!Q10,'تحليل مبيعات'!W:W,'حركة المخزن'!$W$6) -> 0 | X10: =SUMIFS('تحليل مبيعات'!H:H,'تحليل مبيعات'!C:C,'حركة المخزن'!Q10,'تحليل مبيعات'!W:W,'حركة المخزن'!$X$6) -> 7 | Y10: =SUMIFS('تحليل مبيعات'!H:H,'تحليل مبيعات'!C:C,'حركة المخزن'!Q10,'تحليل مبيعات'!W:W,'حركة المخزن'!$Y$6) -> 0 | Z10: =SUMIFS('تحليل مبيعات'!H:H,'تحليل مبيعات'!C:C,'حركة المخزن'!Q10,'تحليل مبيعات'!W:W,'حركة المخزن'!$Z$6) -> 0 | AA10: =SUMIFS('تحليل مبيعات'!H:H,'تحليل مبيعات'!C:C,'حركة المخزن'!Q10,'تحليل مبيعات'!W:W,'حركة المخزن'!$AA$6) -> 0 | AB10: =SUMIFS('تحليل مبيعات'!H:H,'تحليل مبيعات'!C:C,'حركة المخزن'!Q10,'تحليل مبيعات'!W:W,'حركة المخزن'!$AB$6) -> 0 | AC10: =SUMIFS('تحليل مبيعات'!H:H,'تحليل مبيعات'!C:C,'حركة المخزن'!Q10,'تحليل مبيعات'!W:W,'حركة المخزن'!$AC$6) -> 0 | AD10: =SUM(R10:AC10) -> 7
B11: فيتور خط ابيض 14/195 عريض | C11: C0004 | D11: كاوتش | E11: 5 | F11: 1000 | G11: 0 | H11: 0 | I11: =IFERROR(IF(SUMIF('تحليل مبيعات'!C:C, 'حركة المخزن'!B11, 'تحليل مبيعات'!H:H)=0,"",SUMIF('تحليل مبيعات'!C:C, 'حركة المخزن'!B11, 'تحليل مبيعات'!H:H)),"") -> 13 | J11: =IFERROR(IF(SUMIF('تحليل مبيعات'!C:C, 'حركة المخزن'!B11, 'تحليل مبيعات'!L:L)=0,"",SUMIF('تحليل مبيعات'!C:C, 'حركة المخزن'!B11, 'تحليل مبيعات'!L:L)),"") -> 49100 | K11: =IFERROR(E11+G11-I11,"") -> -8 | L11: =IFERROR(F11+H11-J11,"") -> -48100 | M11: 5 | N11: =IF(K11<M11,"أعادة الطلب","يوجد رصيد كافى") -> أعادة الطلب | O11: 50 | Q11: قميص رداتير | R11: =SUMIFS('تحليل مبيعات'!H:H,'تحليل مبيعات'!C:C,'حركة المخزن'!Q11,'تحليل مبيعات'!W:W,'حركة المخزن'!$R$6) -> 0 | S11: =SUMIFS('تحليل مبيعات'!H:H,'تحليل مبيعات'!C:C,'حركة المخزن'!Q11,'تحليل مبيعات'!W:W,'حركة المخزن'!$S$6) -> 0 | T11: =SUMIFS('تحليل مبيعات'!H:H,'تحليل مبيعات'!C:C,'حركة المخزن'!Q11,'تحليل مبيعات'!W:W,'حركة المخزن'!$T$6) -> 0 | U11: =SUMIFS('تحليل مبيعات'!H:H,'تحليل مبيعات'!C:C,'حركة المخزن'!Q11,'تحليل مبيعات'!W:W,'حركة المخزن'!$U$6) -> 0 | V11: =SUMIFS('تحليل مبيعات'!H:H,'تحليل مبيعات'!C:C,'حركة المخزن'!Q11,'تحليل مبيعات'!W:W,'حركة المخزن'!$V$6) -> 0 | W11: =SUMIFS('تحليل مبيعات'!H:H,'تحليل مبيعات'!C:C,'حركة المخزن'!Q11,'تحليل مبيعات'!W:W,'حركة المخزن'!$W$6) -> 0 | X11: =SUMIFS('تحليل مبيعات'!H:H,'تحليل مبيعات'!C:C,'حركة المخزن'!Q11,'تحليل مبيعات'!W:W,'حركة المخزن'!$X$6) -> 8 | Y11: =SUMIFS('تحليل مبيعات'!H:H,'تحليل مبيعات'!C:C,'حركة المخزن'!Q11,'تحليل مبيعات'!W:W,'حركة المخزن'!$Y$6) -> 0 | Z11: =SUMIFS('تحليل مبيعات'!H:H,'تحليل مبيعات'!C:C,'حركة المخزن'!Q11,'تحليل مبيعات'!W:W,'حركة المخزن'!$Z$6) -> 0 | AA11: =SUMIFS('تحليل مبيعات'!H:H,'تحليل مبيعات'!C:C,'حركة المخزن'!Q11,'تحليل مبيعات'!W:W,'حركة المخزن'!$AA$6) -> 0 | AB11: =SUMIFS('تحليل مبيعات'!H:H,'تحليل مبيعات'!C:C,'حركة المخزن'!Q11,'تحليل مبيعات'!W:W,'حركة المخزن'!$AB$6) -> 0 | AC11: =SUMIFS('تحليل مبيعات'!H:H,'تحليل مبيعات'!C:C,'حركة المخزن'!Q11,'تحليل مبيعات'!W:W,'حركة المخزن'!$AC$6) -> 0 | AD11: =SUM(R11:AC11) -> 8
B12: 14/5/114 جنط سبور صينى تويوتا غاطس SLP LG20-VL | C12: C0005 | D12: كاوتش | E12: 5 | F12: 1000 | G12: 0 | H12: 0 | I12: =IFERROR(IF(SUMIF('تحليل مبيعات'!C:C, 'حركة المخزن'!B12, 'تحليل مبيعات'!H:H)=0,"",SUMIF('تحليل مبيعات'!C:C, 'حركة المخزن'!B12, 'تحليل مبيعات'!H:H)),"") -> 4 | J12: =IFERROR(IF(SUMIF('تحليل مبيعات'!C:C, 'حركة المخزن'!B12, 'تحليل مبيعات'!L:L)=0,"",SUMIF('تحليل مبيعات'!C:C, 'حركة المخزن'!B12, 'تحليل مبيعات'!L:L)),"") -> 30700 | K12: =IFERROR(E12+G12-I12,"") -> 1 | L12: =IFERROR(F12+H12-J12,"") -> -29700 | M12: 5 | N12: =IF(K12<M12,"أعادة الطلب","يوجد رصيد كافى") -> أعادة الطلب | O12: 50 | Q12: طقم جوان تويوتا | R12: =SUMIFS('تحليل مبيعات'!H:H,'تحليل مبيعات'!C:C,'حركة المخزن'!Q12,'تحليل مبيعات'!W:W,'حركة المخزن'!$R$6) -> 0 | S12: =SUMIFS('تحليل مبيعات'!H:H,'تحليل مبيعات'!C:C,'حركة المخزن'!Q12,'تحليل مبيعات'!W:W,'حركة المخزن'!$S$6) -> 0 | T12: =SUMIFS('تحليل مبيعات'!H:H,'تحليل مبيعات'!C:C,'حركة المخزن'!Q12,'تحليل مبيعات'!W:W,'حركة المخزن'!$T$6) -> 0 | U12: =SUMIFS('تحليل مبيعات'!H:H,'تحليل مبيعات'!C:C,'حركة المخزن'!Q12,'تحليل مبيعات'!W:W,'حركة المخزن'!$U$6) -> 0 | V12: =SUMIFS('تحليل مبيعات'!H:H,'تحليل مبيعات'!C:C,'حركة المخزن'!Q12,'تحليل مبيعات'!W:W,'حركة المخزن'!$V$6) -> 0 | W12: =SUMIFS('تحليل مبيعات'!H:H,'تحليل مبيعات'!C:C,'حركة المخزن'!Q12,'تحليل مبيعات'!W:W,'حركة المخزن'!$W$6) -> 0 | X12: =SUMIFS('تحليل مبيعات'!H:H,'تحليل مبيعات'!C:C,'حركة المخزن'!Q12,'تحليل مبيعات'!W:W,'حركة المخزن'!$X$6) -> 3 | Y12: =SUMIFS('تحليل مبيعات'!H:H,'تحليل مبيعات'!C:C,'حركة المخزن'!Q12,'تحليل مبيعات'!W:W,'حركة المخزن'!$Y$6) -> 0 | Z12: =SUMIFS('تحليل مبيعات'!H:H,'تحليل مبيعات'!C:C,'حركة المخزن'!Q12,'تحليل مبيعات'!W:W,'حركة المخزن'!$Z$6) -> 0 | AA12: =SUMIFS('تحليل مبيعات'!H:H,'تحليل مبيعات'!C:C,'حركة المخزن'!Q12,'تحليل مبيعات'!W:W,'حركة المخزن'!$AA$6) -> 0 | AB12: =SUMIFS('تحليل مبيعات'!H:H,'تحليل مبيعات'!C:C,'حركة المخزن'!Q12,'تحليل مبيعات'!W:W,'حركة المخزن'!$AB$6) -> 0 | AC12: =SUMIFS('تحليل مبيعات'!H:H,'تحليل مبيعات'!C:C,'حركة المخزن'!Q12,'تحليل مبيعات'!W:W,'حركة المخزن'!$AC$6) -> 0 | AD12: =SUM(R12:AC12) -> 3
B13: 14/5/114 جنط سبور صينى تويوتا غاطس | C13: C0006 | D13: كاوتش | E13: 5 | F13: 1000 | G13: 0 | H13: 0 | I13: =IFERROR(IF(SUMIF('تحليل مبيعات'!C:C, 'حركة المخزن'!B13, 'تحليل مبيعات'!H:H)=0,"",SUMIF('تحليل مبيعات'!C:C, 'حركة المخزن'!B13, 'تحليل مبيعات'!H:H)),"") -> 4 | J13: =IFERROR(IF(SUMIF('تحليل مبيعات'!C:C, 'حركة المخزن'!B13, 'تحليل مبيعات'!L:L)=0,"",SUMIF('تحليل مبيعات'!C:C, 'حركة المخزن'!B13, 'تحليل مبيعات'!L:L)),"") -> 15500 | K13: =IFERROR(E13+G13-I13,"") -> 1 | L13: =IFERROR(F13+H13-J13,"") -> -14500 | M13: 5 | N13: =IF(K13<M13,"أعادة الطلب","يوجد رصيد كافى") -> أعادة الطلب | O13: 40 | Q13: طقم تيل امامى | R13: =SUMIFS('تحليل مبيعات'!H:H,'تحليل مبيعات'!C:C,'حركة المخزن'!Q13,'تحليل مبيعات'!W:W,'حركة المخزن'!$R$6) -> 0 | S13: =SUMIFS('تحليل مبيعات'!H:H,'تحليل مبيعات'!C:C,'حركة المخزن'!Q13,'تحليل مبيعات'!W:W,'حركة المخزن'!$S$6) -> 0 | T13: =SUMIFS('تحليل مبيعات'!H:H,'تحليل مبيعات'!C:C,'حركة المخزن'!Q13,'تحليل مبيعات'!W:W,'حركة المخزن'!$T$6) -> 0 | U13: =SUMIFS('تحليل مبيعات'!H:H,'تحليل مبيعات'!C:C,'حركة المخزن'!Q13,'تحليل مبيعات'!W:W,'حركة المخزن'!$U$6) -> 0 | V13: =SUMIFS('تحليل مبيعات'!H:H,'تحليل مبيعات'!C:C,'حركة المخزن'!Q13,'تحليل مبيعات'!W:W,'حركة المخزن'!$V$6) -> 0 | W13: =SUMIFS('تحليل مبيعات'!H:H,'تحليل مبيعات'!C:C,'حركة المخزن'!Q13,'تحليل مبيعات'!W:W,'حركة المخزن'!$W$6) -> 0 | X13: =SUMIFS('تحليل مبيعات'!H:H,'تحليل مبيعات'!C:C,'حركة المخزن'!Q13,'تحليل مبيعات'!W:W,'حركة المخزن'!$X$6) -> 8 | Y13: =SUMIFS('تحليل مبيعات'!H:H,'تحليل مبيعات'!C:C,'حركة المخزن'!Q13,'تحليل مبيعات'!W:W,'حركة المخزن'!$Y$6) -> 0 | Z13: =SUMIFS('تحليل مبيعات'!H:H,'تحليل مبيعات'!C:C,'حركة المخزن'!Q13,'تحليل مبيعات'!W:W,'حركة المخزن'!$Z$6) -> 0 | AA13: =SUMIFS('تحليل مبيعات'!H:H,'تحليل مبيعات'!C:C,'حركة المخزن'!Q13,'تحليل مبيعات'!W:W,'حركة المخزن'!$AA$6) -> 0 | AB13: =SUMIFS('تحليل مبيعات'!H:H,'تحليل مبيعات'!C:C,'حركة المخزن'!Q13,'تحليل مبيعات'!W:W,'حركة المخزن'!$AB$6) -> 0 | AC13: =SUMIFS('تحليل مبيعات'!H:H,'تحليل مبيعات'!C:C,'حركة المخزن'!Q13,'تحليل مبيعات'!W:W,'حركة المخزن'!$AC$6) -> 0 | AD13: =SUM(R13:AC13) -> 8
B14: فيتور خط ابيض 14/195 كنزة | C14: C0007 | D14: كاوتش | E14: 5 | F14: 1000 | G14: 0 | H14: 0 | I14: =IFERROR(IF(SUMIF('تحليل مبيعات'!C:C, 'حركة المخزن'!B14, 'تحليل مبيعات'!H:H)=0,"",SUMIF('تحليل مبيعات'!C:C, 'حركة المخزن'!B14, 'تحليل مبيعات'!H:H)),"") -> 2 | J14: =IFERROR(IF(SUMIF('تحليل مبيعات'!C:C, 'حركة المخزن'!B14, 'تحليل مبيعات'!L:L)=0,"",SUMIF('تحليل مبيعات'!C:C, 'حركة المخزن'!B14, 'تحليل مبيعات'!L:L)),"") -> 6400 | K14: =IFERROR(E14+G14-I14,"") -> 3 | L14: =IFERROR(F14+H14-J14,"") -> -5400 | M14: 5 | N14: =IF(K14<M14,"أعادة الطلب","يوجد رصيد كافى") -> أعادة الطلب | O14: 100 | Q14: غطاء تنك | R14: =SUMIFS('تحليل مبيعات'!H:H,'تحليل مبيعات'!C:C,'حركة المخزن'!Q14,'تحليل مبيعات'!W:W,'حركة المخزن'!$R$6) -> 0 | S14: =SUMIFS('تحليل مبيعات'!H:H,'تحليل مبيعات'!C:C,'حركة المخزن'!Q14,'تحليل مبيعات'!W:W,'حركة المخزن'!$S$6) -> 0 | T14: =SUMIFS('تحليل مبيعات'!H:H,'تحليل مبيعات'!C:C,'حركة المخزن'!Q14,'تحليل مبيعات'!W:W,'حركة المخزن'!$T$6) -> 0 | U14: =SUMIFS('تحليل مبيعات'!H:H,'تحليل مبيعات'!C:C,'حركة المخزن'!Q14,'تحليل مبيعات'!W:W,'حركة المخزن'!$U$6) -> 0 | V14: =SUMIFS('تحليل مبيعات'!H:H,'تحليل مبيعات'!C:C,'حركة المخزن'!Q14,'تحليل مبيعات'!W:W,'حركة المخزن'!$V$6) -> 0 | W14: =SUMIFS('تحليل مبيعات'!H:H,'تحليل مبيعات'!C:C,'حركة المخزن'!Q14,'تحليل مبيعات'!W:W,'حركة المخزن'!$W$6) -> 0 | X14: =SUMIFS('تحليل مبيعات'!H:H,'تحليل مبيعات'!C:C,'حركة المخزن'!Q14,'تحليل مبيعات'!W:W,'حركة المخزن'!$X$6) -> 1 | Y14: =SUMIFS('تحليل مبيعات'!H:H,'تحليل مبيعات'!C:C,'حركة المخزن'!Q14,'تحليل مبيعات'!W:W,'حركة المخزن'!$Y$6) -> 0 | Z14: =SUMIFS('تحليل مبيعات'!H:H,'تحليل مبيعات'!C:C,'حركة المخزن'!Q14,'تحليل مبيعات'!W:W,'حركة المخزن'!$Z$6) -> 0 | AA14: =SUMIFS('تحليل مبيعات'!H:H,'تحليل مبيعات'!C:C,'حركة المخزن'!Q14,'تحليل مبيعات'!W:W,'حركة المخزن'!$AA$6) -> 0 | AB14: =SUMIFS('تحليل مبيعات'!H:H,'تحليل مبيعات'!C:C,'حركة المخزن'!Q14,'تحليل مبيعات'!W:W,'حركة المخزن'!$AB$6) -> 0 | AC14: =SUMIFS('تحليل مبيعات'!H:H,'تحليل مبيعات'!C:C,'حركة المخزن'!Q14,'تحليل مبيعات'!W:W,'حركة المخزن'!$AC$6) -> 0 | AD14: =SUM(R14:AC14) -> 1
B15: طقم جانط 5 خرم ملاكى 15 | C15: C0008 | D15: كاوتش | E15: 5 | F15: 1000 | G15: 0 | H15: 0 | I15: =IFERROR(IF(SUMIF('تحليل مبيعات'!C:C, 'حركة المخزن'!B15, 'تحليل مبيعات'!H:H)=0,"",SUMIF('تحليل مبيعات'!C:C, 'حركة المخزن'!B15, 'تحليل مبيعات'!H:H)),"") -> 4 | J15: =IFERROR(IF(SUMIF('تحليل مبيعات'!C:C, 'حركة المخزن'!B15, 'تحليل مبيعات'!L:L)=0,"",SUMIF('تحليل مبيعات'!C:C, 'حركة المخزن'!B15, 'تحليل مبيعات'!L:L)),"") -> 22700 | K15: =IFERROR(E15+G15-I15,"") -> 1 | L15: =IFERROR(F15+H15-J15,"") -> -21700 | M15: 5 | N15: =IF(K15<M15,"أعادة الطلب","يوجد رصيد كافى") -> أعادة الطلب | O15: 200 | Q15: طقم بلية صره امامى + اويل سيل | R15: =SUMIFS('تحليل مبيعات'!H:H,'تحليل مبيعات'!C:C,'حركة المخزن'!Q15,'تحليل مبيعات'!W:W,'حركة المخزن'!$R$6) -> 0 | S15: =SUMIFS('تحليل مبيعات'!H:H,'تحليل مبيعات'!C:C,'حركة المخزن'!Q15,'تحليل مبيعات'!W:W,'حركة المخزن'!$S$6) -> 0 | T15: =SUMIFS('تحليل مبيعات'!H:H,'تحليل مبيعات'!C:C,'حركة المخزن'!Q15,'تحليل مبيعات'!W:W,'حركة المخزن'!$T$6) -> 0 | U15: =SUMIFS('تحليل مبيعات'!H:H,'تحليل مبيعات'!C:C,'حركة المخزن'!Q15,'تحليل مبيعات'!W:W,'حركة المخزن'!$U$6) -> 0 | V15: =SUMIFS('تحليل مبيعات'!H:H,'تحليل مبيعات'!C:C,'حركة المخزن'!Q15,'تحليل مبيعات'!W:W,'حركة المخزن'!$V$6) -> 0 | W15: =SUMIFS('تحليل مبيعات'!H:H,'تحليل مبيعات'!C:C,'حركة المخزن'!Q15,'تحليل مبيعات'!W:W,'حركة المخزن'!$W$6) -> 0 | X15: =SUMIFS('تحليل مبيعات'!H:H,'تحليل مبيعات'!C:C,'حركة المخزن'!Q15,'تحليل مبيعات'!W:W,'حركة المخزن'!$X$6) -> 6 | Y15: =SUMIFS('تحليل مبيعات'!H:H,'تحليل مبيعات'!C:C,'حركة المخزن'!Q15,'تحليل مبيعات'!W:W,'حركة المخزن'!$Y$6) -> 1 | Z15: =SUMIFS('تحليل مبيعات'!H:H,'تحليل مبيعات'!C:C,'حركة المخزن'!Q15,'تحليل مبيعات'!W:W,'حركة المخزن'!$Z$6) -> 0 | AA15: =SUMIFS('تحليل مبيعات'!H:H,'تحليل مبيعات'!C:C,'حركة المخزن'!Q15,'تحليل مبيعات'!W:W,'حركة المخزن'!$AA$6) -> 0 | AB15: =SUMIFS('تحليل مبيعات'!H:H,'تحليل مبيعات'!C:C,'حركة المخزن'!Q15,'تحليل مبيعات'!W:W,'حركة المخزن'!$AB$6) -> 0 | AC15: =SUMIFS('تحليل مبيعات'!H:H,'تحليل مبيعات'!C:C,'حركة المخزن'!Q15,'تحليل مبيعات'!W:W,'حركة المخزن'!$AC$6) -> 0 | AD15: =SUM(R15:AC15) -> 7
B16: فيتور خط ابيض 13/185/60 GALAXY F1 | C16: C0009 | D16: كاوتش | E16: 5 | F16: 1000 | G16: 0 | H16: 0 | I16: =IFERROR(IF(SUMIF('تحليل مبيعات'!C:C, 'حركة المخزن'!B16, 'تحليل مبيعات'!H:H)=0,"",SUMIF('تحليل مبيعات'!C:C, 'حركة المخزن'!B16, 'تحليل مبيعات'!H:H)),"") -> 4 | J16: =IFERROR(IF(SUMIF('تحليل مبيعات'!C:C, 'حركة المخزن'!B16, 'تحليل مبيعات'!L:L)=0,"",SUMIF('تحليل مبيعات'!C:C, 'حركة المخزن'!B16, 'تحليل مبيعات'!L:L)),"") -> 7200 | K16: =IFERROR(E16+G16-I16,"") -> 1 | L16: =IFERROR(F16+H16-J16,"") -> -6200 | M16: 5 | N16: =IF(K16<M16,"أعادة الطلب","يوجد رصيد كافى") -> أعادة الطلب | O16: 250 | Q16: تيل خلفى 902317 | R16: =SUMIFS('تحليل مبيعات'!H:H,'تحليل مبيعات'!C:C,'حركة المخزن'!Q16,'تحليل مبيعات'!W:W,'حركة المخزن'!$R$6) -> 0 | S16: =SUMIFS('تحليل مبيعات'!H:H,'تحليل مبيعات'!C:C,'حركة المخزن'!Q16,'تحليل مبيعات'!W:W,'حركة المخزن'!$S$6) -> 0 | T16: =SUMIFS('تحليل مبيعات'!H:H,'تحليل مبيعات'!C:C,'حركة المخزن'!Q16,'تحليل مبيعات'!W:W,'حركة المخزن'!$T$6) -> 0 | U16: =SUMIFS('تحليل مبيعات'!H:H,'تحليل مبيعات'!C:C,'حركة المخزن'!Q16,'تحليل مبيعات'!W:W,'حركة المخزن'!$U$6) -> 0 | V16: =SUMIFS('تحليل مبيعات'!H:H,'تحليل مبيعات'!C:C,'حركة المخزن'!Q16,'تحليل مبيعات'!W:W,'حركة المخزن'!$V$6) -> 0 | W16: =SUMIFS('تحليل مبيعات'!H:H,'تحليل مبيعات'!C:C,'حركة المخزن'!Q16,'تحليل مبيعات'!W:W,'حركة المخزن'!$W$6) -> 0 | X16: =SUMIFS('تحليل مبيعات'!H:H,'تحليل مبيعات'!C:C,'حركة المخزن'!Q16,'تحليل مبيعات'!W:W,'حركة المخزن'!$X$6) -> 6 | Y16: =SUMIFS('تحليل مبيعات'!H:H,'تحليل مبيعات'!C:C,'حركة المخزن'!Q16,'تحليل مبيعات'!W:W,'حركة المخزن'!$Y$6) -> 0 | Z16: =SUMIFS('تحليل مبيعات'!H:H,'تحليل مبيعات'!C:C,'حركة المخزن'!Q16,'تحليل مبيعات'!W:W,'حركة المخزن'!$Z$6) -> 0 | AA16: =SUMIFS('تحليل مبيعات'!H:H,'تحليل مبيعات'!C:C,'حركة المخزن'!Q16,'تحليل مبيعات'!W:W,'حركة المخزن'!$AA$6) -> 0 | AB16: =SUMIFS('تحليل مبيعات'!H:H,'تحليل مبيعات'!C:C,'حركة المخزن'!Q16,'تحليل مبيعات'!W:W,'حركة المخزن'!$AB$6) -> 0 | AC16: =SUMIFS('تحليل مبيعات'!H:H,'تحليل مبيعات'!C:C,'حركة المخزن'!Q16,'تحليل مبيعات'!W:W,'حركة المخزن'!$AC$6) -> 0 | AD16: =SUM(R16:AC16) -> 6
B17: فيتور 14/195 عريض | C17: C0010 | D17: كاوتش | E17: 5 | F17: 1000 | G17: 0 | H17: 0 | I17: =IFERROR(IF(SUMIF('تحليل مبيعات'!C:C, 'حركة المخزن'!B17, 'تحليل مبيعات'!H:H)=0,"",SUMIF('تحليل مبيعات'!C:C, 'حركة المخزن'!B17, 'تحليل مبيعات'!H:H)),"") -> 17 | J17: =IFERROR(IF(SUMIF('تحليل مبيعات'!C:C, 'حركة المخزن'!B17, 'تحليل مبيعات'!L:L)=0,"",SUMIF('تحليل مبيعات'!C:C, 'حركة المخزن'!B17, 'تحليل مبيعات'!L:L)),"") -> 79800 | K17: =IFERROR(E17+G17-I17,"") -> -12 | L17: =IFERROR(F17+H17-J17,"") -> -78800 | M17: 5 | N17: =IF(K17<M17,"أعادة الطلب","يوجد رصيد كافى") -> أعادة الطلب | O17: 150 | Q17: بطارية نسر 70 | R17: =SUMIFS('تحليل مبيعات'!H:H,'تحليل مبيعات'!C:C,'حركة المخزن'!Q17,'تحليل مبيعات'!W:W,'حركة المخزن'!$R$6) -> 0 | S17: =SUMIFS('تحليل مبيعات'!H:H,'تحليل مبيعات'!C:C,'حركة المخزن'!Q17,'تحليل مبيعات'!W:W,'حركة المخزن'!$S$6) -> 0 | T17: =SUMIFS('تحليل مبيعات'!H:H,'تحليل مبيعات'!C:C,'حركة المخزن'!Q17,'تحليل مبيعات'!W:W,'حركة المخزن'!$T$6) -> 0 | U17: =SUMIFS('تحليل مبيعات'!H:H,'تحليل مبيعات'!C:C,'حركة المخزن'!Q17,'تحليل مبيعات'!W:W,'حركة المخزن'!$U$6) -> 0 | V17: =SUMIFS('تحليل مبيعات'!H:H,'تحليل مبيعات'!C:C,'حركة المخزن'!Q17,'تحليل مبيعات'!W:W,'حركة المخزن'!$V$6) -> 0 | W17: =SUMIFS('تحليل مبيعات'!H:H,'تحليل مبيعات'!C:C,'حركة المخزن'!Q17,'تحليل مبيعات'!W:W,'حركة المخزن'!$W$6) -> 0 | X17: =SUMIFS('تحليل مبيعات'!H:H,'تحليل مبيعات'!C:C,'حركة المخزن'!Q17,'تحليل مبيعات'!W:W,'حركة المخزن'!$X$6) -> 1 | Y17: =SUMIFS('تحليل مبيعات'!H:H,'تحليل مبيعات'!C:C,'حركة المخزن'!Q17,'تحليل مبيعات'!W:W,'حركة المخزن'!$Y$6) -> 0 | Z17: =SUMIFS('تحليل مبيعات'!H:H,'تحليل مبيعات'!C:C,'حركة المخزن'!Q17,'تحليل مبيعات'!W:W,'حركة المخزن'!$Z$6) -> 0 | AA17: =SUMIFS('تحليل مبيعات'!H:H,'تحليل مبيعات'!C:C,'حركة المخزن'!Q17,'تحليل مبيعات'!W:W,'حركة المخزن'!$AA$6) -> 0 | AB17: =SUMIFS('تحليل مبيعات'!H:H,'تحليل مبيعات'!C:C,'حركة المخزن'!Q17,'تحليل مبيعات'!W:W,'حركة المخزن'!$AB$6) -> 0 | AC17: =SUMIFS('تحليل مبيعات'!H:H,'تحليل مبيعات'!C:C,'حركة المخزن'!Q17,'تحليل مبيعات'!W:W,'حركة المخزن'!$AC$6) -> 0 | AD17: =SUM(R17:AC17) -> 1
B18: فيتور 14/195 كنزة | C18: C0011 | D18: كاوتش | E18: 5 | F18: 1000 | G18: 0 | H18: 0 | I18: =IFERROR(IF(SUMIF('تحليل مبيعات'!C:C, 'حركة المخزن'!B18, 'تحليل مبيعات'!H:H)=0,"",SUMIF('تحليل مبيعات'!C:C, 'حركة المخزن'!B18, 'تحليل مبيعات'!H:H)),"") -> 9 | J18: =IFERROR(IF(SUMIF('تحليل مبيعات'!C:C, 'حركة المخزن'!B18, 'تحليل مبيعات'!L:L)=0,"",SUMIF('تحليل مبيعات'!C:C, 'حركة المخزن'!B18, 'تحليل مبيعات'!L:L)),"") -> 39750 | K18: =IFERROR(E18+G18-I18,"") -> -4 | L18: =IFERROR(F18+H18-J18,"") -> -38750 | M18: 5 | N18: =IF(K18<M18,"أعادة الطلب","يوجد رصيد كافى") -> أعادة الطلب | O18: 150 | Q18: شريحة اسبرتير | R18: =SUMIFS('تحليل مبيعات'!H:H,'تحليل مبيعات'!C:C,'حركة المخزن'!Q18,'تحليل مبيعات'!W:W,'حركة المخزن'!$R$6) -> 0 | S18: =SUMIFS('تحليل مبيعات'!H:H,'تحليل مبيعات'!C:C,'حركة المخزن'!Q18,'تحليل مبيعات'!W:W,'حركة المخزن'!$S$6) -> 0 | T18: =SUMIFS('تحليل مبيعات'!H:H,'تحليل مبيعات'!C:C,'حركة المخزن'!Q18,'تحليل مبيعات'!W:W,'حركة المخزن'!$T$6) -> 0 | U18: =SUMIFS('تحليل مبيعات'!H:H,'تحليل مبيعات'!C:C,'حركة المخزن'!Q18,'تحليل مبيعات'!W:W,'حركة المخزن'!$U$6) -> 0 | V18: =SUMIFS('تحليل مبيعات'!H:H,'تحليل مبيعات'!C:C,'حركة المخزن'!Q18,'تحليل مبيعات'!W:W,'حركة المخزن'!$V$6) -> 0 | W18: =SUMIFS('تحليل مبيعات'!H:H,'تحليل مبيعات'!C:C,'حركة المخزن'!Q18,'تحليل مبيعات'!W:W,'حركة المخزن'!$W$6) -> 0 | X18: =SUMIFS('تحليل مبيعات'!H:H,'تحليل مبيعات'!C:C,'حركة المخزن'!Q18,'تحليل مبيعات'!W:W,'حركة المخزن'!$X$6) -> 3 | Y18: =SUMIFS('تحليل مبيعات'!H:H,'تحليل مبيعات'!C:C,'حركة المخزن'!Q18,'تحليل مبيعات'!W:W,'حركة المخزن'!$Y$6) -> 0 | Z18: =SUMIFS('تحليل مبيعات'!H:H,'تحليل مبيعات'!C:C,'حركة المخزن'!Q18,'تحليل مبيعات'!W:W,'حركة المخزن'!$Z$6) -> 0 | AA18: =SUMIFS('تحليل مبيعات'!H:H,'تحليل مبيعات'!C:C,'حركة المخزن'!Q18,'تحليل مبيعات'!W:W,'حركة المخزن'!$AA$6) -> 0 | AB18: =SUMIFS('تحليل مبيعات'!H:H,'تحليل مبيعات'!C:C,'حركة المخزن'!Q18,'تحليل مبيعات'!W:W,'حركة المخزن'!$AB$6) -> 0 | AC18: =SUMIFS('تحليل مبيعات'!H:H,'تحليل مبيعات'!C:C,'حركة المخزن'!Q18,'تحليل مبيعات'!W:W,'حركة المخزن'!$AC$6) -> 0 | AD18: =SUM(R18:AC18) -> 3
B19: طقم جانط 14 BLP LG20-VL | C19: C0012 | D19: كاوتش | E19: 5 | F19: 1000 | G19: 0 | H19: 0 | I19: =IFERROR(IF(SUMIF('تحليل مبيعات'!C:C, 'حركة المخزن'!B19, 'تحليل مبيعات'!H:H)=0,"",SUMIF('تحليل مبيعات'!C:C, 'حركة المخزن'!B19, 'تحليل مبيعات'!H:H)),"") -> 4 | J19: =IFERROR(IF(SUMIF('تحليل مبيعات'!C:C, 'حركة المخزن'!B19, 'تحليل مبيعات'!L:L)=0,"",SUMIF('تحليل مبيعات'!C:C, 'حركة المخزن'!B19, 'تحليل مبيعات'!L:L)),"") -> 17650 | K19: =IFERROR(E19+G19-I19,"") -> 1 | L19: =IFERROR(F19+H19-J19,"") -> -16650 | M19: 5 | N19: =IF(K19<M19,"أعادة الطلب","يوجد رصيد كافى") -> أعادة الطلب | O19: 125 | Q19: بطارية كلورايد 70 | R19: =SUMIFS('تحليل مبيعات'!H:H,'تحليل مبيعات'!C:C,'حركة المخزن'!Q19,'تحليل مبيعات'!W:W,'حركة المخزن'!$R$6) -> 0 | S19: =SUMIFS('تحليل مبيعات'!H:H,'تحليل مبيعات'!C:C,'حركة المخزن'!Q19,'تحليل مبيعات'!W:W,'حركة المخزن'!$S$6) -> 0 | T19: =SUMIFS('تحليل مبيعات'!H:H,'تحليل مبيعات'!C:C,'حركة المخزن'!Q19,'تحليل مبيعات'!W:W,'حركة المخزن'!$T$6) -> 0 | U19: =SUMIFS('تحليل مبيعات'!H:H,'تحليل مبيعات'!C:C,'حركة المخزن'!Q19,'تحليل مبيعات'!W:W,'حركة المخزن'!$U$6) -> 0 | V19: =SUMIFS('تحليل مبيعات'!H:H,'تحليل مبيعات'!C:C,'حركة المخزن'!Q19,'تحليل مبيعات'!W:W,'حركة المخزن'!$V$6) -> 0 | W19: =SUMIFS('تحليل مبيعات'!H:H,'تحليل مبيعات'!C:C,'حركة المخزن'!Q19,'تحليل مبيعات'!W:W,'حركة المخزن'!$W$6) -> 0 | X19: =SUMIFS('تحليل مبيعات'!H:H,'تحليل مبيعات'!C:C,'حركة المخزن'!Q19,'تحليل مبيعات'!W:W,'حركة المخزن'!$X$6) -> 3 | Y19: =SUMIFS('تحليل مبيعات'!H:H,'تحليل مبيعات'!C:C,'حركة المخزن'!Q19,'تحليل مبيعات'!W:W,'حركة المخزن'!$Y$6) -> 0 | Z19: =SUMIFS('تحليل مبيعات'!H:H,'تحليل مبيعات'!C:C,'حركة المخزن'!Q19,'تحليل مبيعات'!W:W,'حركة المخزن'!$Z$6) -> 0 | AA19: =SUMIFS('تحليل مبيعات'!H:H,'تحليل مبيعات'!C:C,'حركة المخزن'!Q19,'تحليل مبيعات'!W:W,'حركة المخزن'!$AA$6) -> 0 | AB19: =SUMIFS('تحليل مبيعات'!H:H,'تحليل مبيعات'!C:C,'حركة المخزن'!Q19,'تحليل مبيعات'!W:W,'حركة المخزن'!$AB$6) -> 0 | AC19: =SUMIFS('تحليل مبيعات'!H:H,'تحليل مبيعات'!C:C,'حركة المخزن'!Q19,'تحليل مبيعات'!W:W,'حركة المخزن'!$AC$6) -> 0 | AD19: =SUM(R19:AC19) -> 3
... B107: كوستبان | C107: C0100 | D107: قطع غيار | E107: 10 | F107: 10000 | G107: 0 | H107: 0 | I107: =IFERROR(IF(SUMIF('تحليل مبيعات'!C:C, 'حركة المخزن'!B107, 'تحليل مبيعات'!H:H)=0,"",SUMIF('تحليل مبيعات'!C:C, 'حركة المخزن'!B107, 'تحليل مبيعات'!H:H)),"") -> 1 | J107: =IFERROR(IF(SUMIF('تحليل مبيعات'!C:C, 'حركة المخزن'!B107, 'تحليل مبيعات'!L:L)=0,"",SUMIF('تحليل مبيعات'!C:C, 'حركة المخزن'!B107, 'تحليل مبيعات'!L:L)),"") -> 800 | K107: =IFERROR(E107+G107-I107,"") -> 9 | L107: =IFERROR(F107+H107-J107,"") -> 9200 | M107: 5 | N107: =IF(K107<M107,"أعادة الطلب","يوجد رصيد كافى") -> يوجد رصيد كافى | O107: 195 | Q107: بازبوز مسحات طقم | R107: =SUMIFS('تحليل مبيعات'!H:H,'تحليل مبيعات'!C:C,'حركة المخزن'!Q107,'تحليل مبيعات'!W:W,'حركة المخزن'!$R$6) -> 0 | S107: =SUMIFS('تحليل مبيعات'!H:H,'تحليل مبيعات'!C:C,'حركة المخزن'!Q107,'تحليل مبيعات'!W:W,'حركة المخزن'!$S$6) -> 0 | T107: =SUMIFS('تحليل مبيعات'!H:H,'تحليل مبيعات'!C:C,'حركة المخزن'!Q107,'تحليل مبيعات'!W:W,'حركة المخزن'!$T$6) -> 0 | U107: =SUMIFS('تحليل مبيعات'!H:H,'تحليل مبيعات'!C:C,'حركة المخزن'!Q107,'تحليل مبيعات'!W:W,'حركة المخزن'!$U$6) -> 0 | V107: =SUMIFS('تحليل مبيعات'!H:H,'تحليل مبيعات'!C:C,'حركة المخزن'!Q107,'تحليل مبيعات'!W:W,'حركة المخزن'!$V$6) -> 0 | W107: =SUMIFS('تحليل مبيعات'!H:H,'تحليل مبيعات'!C:C,'حركة المخزن'!Q107,'تحليل مبيعات'!W:W,'حركة المخزن'!$W$6) -> 0 | X107: =SUMIFS('تحليل مبيعات'!H:H,'تحليل مبيعات'!C:C,'حركة المخزن'!Q107,'تحليل مبيعات'!W:W,'حركة المخزن'!$X$6) -> 2 | Y107: =SUMIFS('تحليل مبيعات'!H:H,'تحليل مبيعات'!C:C,'حركة المخزن'!Q107,'تحليل مبيعات'!W:W,'حركة المخزن'!$Y$6) -> 0 | Z107: =SUMIFS('تحليل مبيعات'!H:H,'تحليل مبيعات'!C:C,'حركة المخزن'!Q107,'تحليل مبيعات'!W:W,'حركة المخزن'!$Z$6) -> 0 | AA107: =SUMIFS('تحليل مبيعات'!H:H,'تحليل مبيعات'!C:C,'حركة المخزن'!Q107,'تحليل مبيعات'!W:W,'حركة المخزن'!$AA$6) -> 0 | AB107: =SUMIFS('تحليل مبيعات'!H:H,'تحليل مبيعات'!C:C,'حركة المخزن'!Q107,'تحليل مبيعات'!W:W,'حركة المخزن'!$AB$6) -> 0 | AC107: =SUMIFS('تحليل مبيعات'!H:H,'تحليل مبيعات'!C:C,'حركة المخزن'!Q107,'تحليل مبيعات'!W:W,'حركة المخزن'!$AC$6) -> 0 | AD107: =SUM(R107:AC107) -> 2
B108: بلية دبرياج عالية | C108: C0101 | D108: قطع غيار | E108: 10 | F108: 10000 | G108: =IFERROR(IF(SUMIF(المشتريات!C:C, 'حركة المخزن'!B108, المشتريات!F:F)=0,"",SUMIF(المشتريات!C:C, 'حركة المخزن'!B108, المشتريات!F:F)),"0") | H108: =IFERROR(IF(SUMIF(المشتريات!C:C, 'حركة المخزن'!B108, المشتريات!I:I)=0,"",SUMIF(المشتريات!C:C, 'حركة المخزن'!B108, المشتريات!I:I)),"0") | I108: =IFERROR(IF(SUMIF('تحليل مبيعات'!C:C, 'حركة المخزن'!B108, 'تحليل مبيعات'!H:H)=0,"",SUMIF('تحليل مبيعات'!C:C, 'حركة المخزن'!B108, 'تحليل مبيعات'!H:H)),"") -> 4 | J108: =IFERROR(IF(SUMIF('تحليل مبيعات'!C:C, 'حركة المخزن'!B108, 'تحليل مبيعات'!L:L)=0,"",SUMIF('تحليل مبيعات'!C:C, 'حركة المخزن'!B108, 'تحليل مبيعات'!L:L)),"") -> 770 | K108: =IFERROR(E108+G108-I108,"") | L108: =IFERROR(F108+H108-J108,"") | M108: 5 | N108: =IF(K108<M108,"أعادة الطلب","يوجد رصيد كافى") -> يوجد رصيد كافى | O108: 200 | Q108: طقم سلم باب جان بى | R108: =SUMIFS('تحليل مبيعات'!H:H,'تحليل مبيعات'!C:C,'حركة المخزن'!Q108,'تحليل مبيعات'!W:W,'حركة المخزن'!$R$6) -> 0 | S108: =SUMIFS('تحليل مبيعات'!H:H,'تحليل مبيعات'!C:C,'حركة المخزن'!Q108,'تحليل مبيعات'!W:W,'حركة المخزن'!$S$6) -> 0 | T108: =SUMIFS('تحليل مبيعات'!H:H,'تحليل مبيعات'!C:C,'حركة المخزن'!Q108,'تحليل مبيعات'!W:W,'حركة المخزن'!$T$6) -> 0 | U108: =SUMIFS('تحليل مبيعات'!H:H,'تحليل مبيعات'!C:C,'حركة المخزن'!Q108,'تحليل مبيعات'!W:W,'حركة المخزن'!$U$6) -> 0 | V108: =SUMIFS('تحليل مبيعات'!H:H,'تحليل مبيعات'!C:C,'حركة المخزن'!Q108,'تحليل مبيعات'!W:W,'حركة المخزن'!$V$6) -> 0 | W108: =SUMIFS('تحليل مبيعات'!H:H,'تحليل مبيعات'!C:C,'حركة المخزن'!Q108,'تحليل مبيعات'!W:W,'حركة المخزن'!$W$6) -> 0 | X108: =SUMIFS('تحليل مبيعات'!H:H,'تحليل مبيعات'!C:C,'حركة المخزن'!Q108,'تحليل مبيعات'!W:W,'حركة المخزن'!$X$6) -> 2 | Y108: =SUMIFS('تحليل مبيعات'!H:H,'تحليل مبيعات'!C:C,'حركة المخزن'!Q108,'تحليل مبيعات'!W:W,'حركة المخزن'!$Y$6) -> 0 | Z108: =SUMIFS('تحليل مبيعات'!H:H,'تحليل مبيعات'!C:C,'حركة المخزن'!Q108,'تحليل مبيعات'!W:W,'حركة المخزن'!$Z$6) -> 0 | AA108: =SUMIFS('تحليل مبيعات'!H:H,'تحليل مبيعات'!C:C,'حركة المخزن'!Q108,'تحليل مبيعات'!W:W,'حركة المخزن'!$AA$6) -> 0 | AB108: =SUMIFS('تحليل مبيعات'!H:H,'تحليل مبيعات'!C:C,'حركة المخزن'!Q108,'تحليل مبيعات'!W:W,'حركة المخزن'!$AB$6) -> 0 | AC108: =SUMIFS('تحليل مبيعات'!H:H,'تحليل مبيعات'!C:C,'حركة المخزن'!Q108,'تحليل مبيعات'!W:W,'حركة المخزن'!$AC$6) -> 0 | AD108: =SUM(R108:AC108) -> 2
